Workbook

Sheet DASHBOARD
B2: GRADEBOOK PERFORMANCE DASHBOARD
B3: B.Tech. Semester I | Mathematics & Computing | 2024 Batch | 100 Students
B5: Total Students | D5: Passed | F5: Failed | H5: Overall Pass % | J5: Class Average %
B6: =COUNTA('FINAL SHEET'!E15:E114) -> 100 | D6: ='FINAL SHEET'!V15 -> 91 | F6: ='FINAL SHEET'!V18 -> 9 | H6: =ROUND(D6/B6*100,1)&"%" -> 91% | J6: =ROUND(AVERAGE('FINAL SHEET'!R15:R114),1)&"%" -> 49.8%
B9: SUBJECT-WISE PERFORMANCE | I9: OVERALL GRADE DISTRIBUTION
B11: Subject | C11: Avg Marks | D11: Max Marks | E11: Avg % | F11: Passed | G11: Failed | I11: Grade Band | J11: Students
B12: =SCHEME!F18 -> Introduction to Computing | C12: =ROUND(AVERAGE('FINAL SHEET'!F15:F114),1) -> 48.1 | D12: =SCHEME!M18 -> 100 | E12: =ROUND(C12/D12*100,1) -> 48.1 | F12: ='SUB-1'!Q17 -> 78 | G12: ='SUB-1'!Q18 -> 22 | I12: A (90-100) | J12: =COUNTIFS('FINAL SHEET'!R15:R114,">=90",'FINAL SHEET'!R15:R114,"<=100") -> 1
B13: =SCHEME!F19 -> Computer Programming | C13: =ROUND(AVERAGE('FINAL SHEET'!G15:G114),1) -> 48.9 | D13: =SCHEME!M19 -> 100 | E13: =ROUND(C13/D13*100,1) -> 48.9 | F13: ='SUB- 2'!P16 -> 86 | G13: ='SUB- 2'!P17 -> 14 | I13: B (60-89) | J13: =COUNTIFS('FINAL SHEET'!R15:R114,">=60",'FINAL SHEET'!R15:R114,"<=89") -> 6
B14: =SCHEME!F20 -> Advanced Calculus | C14: =ROUND(AVERAGE('FINAL SHEET'!H15:H114),1) -> 50.3 | D14: =SCHEME!M20 -> 100 | E14: =ROUND(C14/D14*100,1) -> 50.3 | F14: ='SUB-3'!Q17 -> 89 | G14: ='SUB-3'!Q18 -> 11 | I14: C (45-59) | J14: =COUNTIFS('FINAL SHEET'!R15:R114,">=45",'FINAL SHEET'!R15:R114,"<=59") -> 67
B15: =SCHEME!F21 -> Digital Logic Design | C15: =ROUND(AVERAGE('FINAL SHEET'!I15:I114),1) -> 50.8 | D15: =SCHEME!M21 -> 100 | E15: =ROUND(C15/D15*100,1) -> 50.8 | F15: ='SUB-4'!Q16 -> 87 | G15: ='SUB-4'!Q17 -> 13 | I15: D (35-44) | J15: =COUNTIFS('FINAL SHEET'!R15:R114,">=35",'FINAL SHEET'!R15:R114,"<=44") -> 24
B16: =SCHEME!F22 -> Differential Equations | C16: =ROUND(AVERAGE('FINAL SHEET'!J15:J114),1) -> 50.2 | D16: =SCHEME!M22 -> 100 | E16: =ROUND(C16/D16*100,1) -> 50.2 | F16: ='SUB-5'!Q16 -> 81 | G16: ='SUB-5'!Q17 -> 19 | I16: F (<35) | J16: =COUNTIFS('FINAL SHEET'!R15:R114,">=0",'FINAL SHEET'!R15:R114,"<=34") -> 0
B17: =SCHEME!F23 -> Computer Programming Lab | C17: =ROUND(AVERAGE('FINAL SHEET'!K15:K114),1) -> 52.2 | D17: =SCHEME!M23 -> 100 | E17: =ROUND(C17/D17*100,1) -> 52.2 | F17: ='SUB-6'!M17 -> 78 | G17: ='SUB-6'!M18 -> 22
B18: =SCHEME!F24 -> Computing Lab for Data Analysis | C18: =ROUND(AVERAGE('FINAL SHEET'!L15:L114),1) -> 52.4 | D18: =SCHEME!M24 -> 100 | E18: =ROUND(C18/D18*100,1) -> 52.4 | F18: ='SUB-7'!M16 -> 70 | G18: ='SUB-7'!M17 -> 30
B19: =SCHEME!F25 -> Semester Proficiency | C19: =ROUND(AVERAGE('FINAL SHEET'!M15:M114),1) -> 23.4 | D19: =SCHEME!M25 -> 50 | E19: =ROUND(C19/D19*100,1) -> 46.8 | F19: ='SUB-8'!M16 -> 67 | G19: ='SUB-8'!M17 -> 33
B20: =SCHEME!F26 -> Micro Project-1 | C20: =ROUND(AVERAGE('FINAL SHEET'!N15:N114),1) -> 47.7 | D20: =SCHEME!M26 -> 100 | E20: =ROUND(C20/D20*100,1) -> 47.7 | F20: ='SUB-9'!M16 -> 67 | G20: ='SUB-9'!M17 -> 33
B21: =SCHEME!F27 -> Language Lab | C21: =ROUND(AVERAGE('FINAL SHEET'!O15:O114),1) -> 49.3 | D21: =SCHEME!M27 -> 100 | E21: =ROUND(C21/D21*100,1) -> 49.3 | F21: ='SUB-10'!M16 -> 64 | G21: ='SUB-10'!M17 -> 36
B22: =SCHEME!F28 -> Novel Engaging Course | C22: =ROUND(AVERAGE('FINAL SHEET'!P15:P114),1) -> 25 | D22: =SCHEME!M28 -> 50 | E22: =ROUND(C22/D22*100,1) -> 50 | F22: ='SUB- NEC'!M15 -> 66 | G22: ='SUB- NEC'!M16 -> 34
B25: TOP 10 PERFORMERS
B27: Rank | C27: Enrollment No. | D27: Student Name | E27: Total Marks | F27: Overall %
B28: 1 | C28: =INDEX('FINAL SHEET'!$E$15:$E$114,MATCH(E28,'FINAL SHEET'!$Q$15:$Q$114,0)) -> BTMC24O1087 | D28: =IFERROR(VLOOKUP(C28,'STUDENT INFO'!$C$15:$I$114,7,FALSE()),"") -> PARUL AGRAWAL | E28: =LARGE('FINAL SHEET'!$Q$15:$Q$114,1) -> 923 | F28: =ROUND(E28/1000*100,1) -> 92.3
B29: 2 | C29: =INDEX('FINAL SHEET'!$E$15:$E$114,MATCH(E29,'FINAL SHEET'!$Q$15:$Q$114,0)) -> BTMC24O1021 | D29: =IFERROR(VLOOKUP(C29,'STUDENT INFO'!$C$15:$I$114,7,FALSE()),"") -> ANANYA DUBEY | E29: =LARGE('FINAL SHEET'!$Q$15:$Q$114,2) -> 827 | F29: =ROUND(E29/1000*100,1) -> 82.7
B30: 3 | C30: =INDEX('FINAL SHEET'!$E$15:$E$114,MATCH(E30,'FINAL SHEET'!$Q$15:$Q$114,0)) -> BTMC24O1088 | D30: =IFERROR(VLOOKUP(C30,'STUDENT INFO'!$C$15:$I$114,7,FALSE()),"") -> PIYUSH VISHWAKARMA | E30: =LARGE('FINAL SHEET'!$Q$15:$Q$114,3) -> 826 | F30: =ROUND(E30/1000*100,1) -> 82.6
B31: 4 | C31: =INDEX('FINAL SHEET'!$E$15:$E$114,MATCH(E31,'FINAL SHEET'!$Q$15:$Q$114,0)) -> BTMC24O1016 | D31: =IFERROR(VLOOKUP(C31,'STUDENT INFO'!$C$15:$I$114,7,FALSE()),"") -> AJEET PRATAP SINGH KUSTWAR | E31: =LARGE('FINAL SHEET'!$Q$15:$Q$114,4) -> 651 | F31: =ROUND(E31/1000*100,1) -> 65.1
B32: 5 | C32: =INDEX('FINAL SHEET'!$E$15:$E$114,MATCH(E32,'FINAL SHEET'!$Q$15:$Q$114,0)) -> BTMC24O1072 | D32: =IFERROR(VLOOKUP(C32,'STUDENT INFO'!$C$15:$I$114,7,FALSE()),"") -> MOHIT MISHRA | E32: =LARGE('FINAL SHEET'!$Q$15:$Q$114,5) -> 606 | F32: =ROUND(E32/1000*100,1) -> 60.6
B33: 6 | C33: =INDEX('FINAL SHEET'!$E$15:$E$114,MATCH(E33,'FINAL SHEET'!$Q$15:$Q$114,0)) -> BTMC24O1095 | D33: =IFERROR(VLOOKUP(C33,'STUDENT INFO'!$C$15:$I$114,7,FALSE()),"") -> PRIYANSHU SHUKLA | E33: =LARGE('FINAL SHEET'!$Q$15:$Q$114,6) -> 603 | F33: =ROUND(E33/1000*100,1) -> 60.3
B34: 7 | C34: =INDEX('FINAL SHEET'!$E$15:$E$114,MATCH(E34,'FINAL SHEET'!$Q$15:$Q$114,0)) -> BTMC24O1097 | D34: =IFERROR(VLOOKUP(C34,'STUDENT INFO'!$C$15:$I$114,7,FALSE()),"") -> RAGHVENDRA SAHU | E34: =LARGE('FINAL SHEET'!$Q$15:$Q$114,7) -> 602 | F34: =ROUND(E34/1000*100,1) -> 60.2
B35: 8 | C35: =INDEX('FINAL SHEET'!$E$15:$E$114,MATCH(E35,'FINAL SHEET'!$Q$15:$Q$114,0)) -> BTMC24O1046 | D35: =IFERROR(VLOOKUP(C35,'STUDENT INFO'!$C$15:$I$114,7,FALSE()),"") -> HARSHIT SHARMA | E35: =LARGE('FINAL SHEET'!$Q$15:$Q$114,8) -> 587 | F35: =ROUND(E35/1000*100,1) -> 58.7
B36: 9 | C36: =INDEX('FINAL SHEET'!$E$15:$E$114,MATCH(E36,'FINAL SHEET'!$Q$15:$Q$114,0)) -> BTMC24O1033 | D36: =IFERROR(VLOOKUP(C36,'STUDENT INFO'!$C$15:$I$114,7,FALSE()),"") -> AYUSH GUPTA | E36: =LARGE('FINAL SHEET'!$Q$15:$Q$114,9) -> 585 | F36: =ROUND(E36/1000*100,1) -> 58.5
B37: 10 | C37: =INDEX('FINAL SHEET'!$E$15:$E$114,MATCH(E37,'FINAL SHEET'!$Q$15:$Q$114,0)) -> BTMC24O1037 | D37: =IFERROR(VLOOKUP(C37,'STUDENT INFO'!$C$15:$I$114,7,FALSE()),"") -> DEVANSH RAI | E37: =LARGE('FINAL SHEET'!$Q$15:$Q$114,10) -> 583 | F37: =ROUND(E37/1000*100,1) -> 58.3

Sheet MARHSHEET
A2: माधव प्रौद्योगिकी एवं विज्ञान संस्थान, ग्वालियर (म.प्र.), भारत
A3: Madhav Institute of Technology & Science DU, Gwalior (M.P.), INDIA
A4: Deemed University
A5: (Declared under Distinct Category by Ministry of Education, Government of India)
A6: NAAC ACCREDITED WITH A++ GRADE
A7: MARKSHEET
A10: STUDENT NAME: | C10: =IFERROR(VLOOKUP($C$15,'STUDENT INFO'!$C$15:$U$114,7,FALSE()),"Not Found") -> ANANYA DUBEY | G10: COURSE: | H10: =IFERROR(VLOOKUP($C$15,'STUDENT INFO'!$C$15:$U$114,18,FALSE()),"Not Found") -> B.Tech.
A11: FATHER'S NAME: | C11: =IFERROR(VLOOKUP($C$15,'STUDENT INFO'!$C$15:$U$114,10,FALSE()),"Not Found") -> AHSISH DUBEY | G11: BRANCH: | H11: =IFERROR(VLOOKUP($C$15,'STUDENT INFO'!$C$15:$U$114,19,FALSE()),"Not Found") -> Mathematics and Computing
A12: MOTHER'S NAME: | C12: =IFERROR(VLOOKUP($C$15,'STUDENT INFO'!$C$15:$U$114,13,FALSE()),"Not Found") -> ARCHNA DUBEY | G12: SEMESTER: | H12: =ROMAN(1) -> I
A13: D.O.B: | C13: =IFERROR(VLOOKUP($C$15,'STUDENT INFO'!$C$15:$U$114,16,FALSE()),"Not Found") -> 38566
A15: ENROLLMENT NO.: | C15: BTMC24O1021
A19: S.NO | B19: SUBJECT CODE | D19: SUBJECT NAME | F19: TOTAL | G19: OBTAINED | H19: TOTAL CREDIT | I19: CREDIT | J19: GRADE
A20: 1 | B20: ='SUB-1'!E11 -> 25241101 | D20: =SCHEME!F18 -> Introduction to Computing | F20: =SCHEME!M18 -> 100 | G20: =IFERROR(VLOOKUP($C$15,'FINAL SHEET'!$E$15:$T$114,2,FALSE()),"Not Found") -> 67 | H20: 3 | I20: =IFERROR(VLOOKUP(C15,'SUB-1'!E15:M114,9,FALSE()),"Not Found") -> 2 | J20: =IF($G$20>89,"A",IF($G$20>59,"B",IF($G$20>44,"C",IF($G$20>34,"D","F")))) -> B
A21: 2 | B21: ='SUB- 2'!D11 -> 25241102 | D21: =SCHEME!F19 -> Computer Programming | F21: =SCHEME!M19 -> 100 | G21: =IFERROR(VLOOKUP($C$15,'FINAL SHEET'!$E$15:$T$114,3,FALSE()),"Not Found") -> 77 | H21: 2 | I21: =IFERROR(VLOOKUP(C15,'SUB- 2'!D15:L114,9,FALSE()),"Not Found") -> 2 | J21: =IF(G21>89,"A",IF(G21>59,"B",IF(G21>44,"C",IF(G21>34,"D","F")))) -> B
A22: 3 | B22: ='SUB-3'!E11 -> 25241103 | D22: =SCHEME!F20 -> Advanced Calculus | F22: =SCHEME!M20 -> 100 | G22: =IFERROR(VLOOKUP($C$15,'FINAL SHEET'!$E$15:$T$114,4,FALSE()),"Not Found") -> 96 | H22: 3 | I22: =IFERROR(VLOOKUP(C15,'SUB-3'!E15:M114,9,FALSE()),"Not Found") -> 3 | J22: =IF(G22>89,"A",IF(G22>59,"B",IF(G22>44,"C",IF(G22>34,"D","F")))) -> A
A23: 4 | B23: ='SUB-4'!E11 -> 25241104 | D23: =SCHEME!F21 -> Digital Logic Design | F23: =SCHEME!M21 -> 100 | G23: =IFERROR(VLOOKUP($C$15,'FINAL SHEET'!$E$15:$T$114,5,FALSE()),"Not Found") -> 81 | H23: 3 | I23: =IFERROR(VLOOKUP(C15,'SUB-4'!E15:M114,9,FALSE()),"Not Found") -> 3 | J23: =IF(G23>89,"A",IF(G23>59,"B",IF(G23>44,"C",IF(G23>34,"D","F")))) -> B
A24: 5 | B24: ='SUB-5'!E11 -> 25241105 | D24: =SCHEME!F22 -> Differential Equations | F24: =SCHEME!M22 -> 100 | G24: =IFERROR(VLOOKUP($C$15,'FINAL SHEET'!$E$15:$T$114,6,FALSE()),"Not Found") -> 80 | H24: 3 | I24: =IFERROR(VLOOKUP(C15,'SUB-5'!E15:M114,9,FALSE()),"Not Found") -> 3 | J24: =IF(G24>89,"A",IF(G24>59,"B",IF(G24>44,"C",IF(G24>34,"D","F")))) -> B
A25: 6 | B25: ='SUB-6'!E11 -> 25241106 | D25: =SCHEME!F23 -> Computer Programming Lab | F25: =SCHEME!M23 -> 100 | G25: =IFERROR(VLOOKUP($C$15,'FINAL SHEET'!$E$15:$T$114,7,FALSE()),"Not Found") -> 90 | H25: 1 | I25: =IFERROR(VLOOKUP(C15,'SUB-6'!E16:J115,6,FALSE()),"Not Found") -> 1 | J25: =IF(G25>89,"A",IF(G25>59,"B",IF(G25>44,"C",IF(G25>34,"D","F")))) -> A
A26: 7 | B26: ='SUB-7'!E11 -> 25241107 | D26: =SCHEME!F24 -> Computing Lab for Data Analysis | F26: =SCHEME!M24 -> 100 | G26: =IFERROR(VLOOKUP($C$15,'FINAL SHEET'!$E$15:$T$114,8,FALSE()),"Not Found") -> 90 | H26: 1 | I26: =IFERROR(VLOOKUP(C15,'SUB-7'!E16:J115,6,FALSE()),"Not Found") -> 1 | J26: =IF(G26>89,"A",IF(G26>59,"B",IF(G26>44,"C",IF(G26>34,"D","F")))) -> A
A27: 8 | B27: ='SUB-8'!E11 -> 25241108 | D27: =SCHEME!F25 -> Semester Proficiency | F27: =SCHEME!M25 -> 50 | G27: =IFERROR(VLOOKUP($C$15,'FINAL SHEET'!$E$15:$T$114,9,FALSE()),"Not Found") -> 30 | H27: 1 | I27: =IFERROR(VLOOKUP(C15,'SUB-8'!E16:J115,6,FALSE()),"Not Found") -> 1 | J27: =IF(G27>39,"A",IF(G27>29,"B",IF(G27>19,"C",IF(G27>15,"D","F")))) -> B
A28: 9 | B28: ='SUB-9'!E12 -> 25241109 | D28: =SCHEME!F26 -> Micro Project-1 | F28: =SCHEME!M26 -> 100 | G28: =IFERROR(VLOOKUP($C$15,'FINAL SHEET'!$E$15:$T$114,10,FALSE()),"Not Found") -> 73 | H28: 1 | I28: =IFERROR(VLOOKUP(C15,'SUB-9'!E17:J116,6,FALSE()),"Not Found") -> 1 | J28: =IF(G28>89,"A",IF(G28>59,"B",IF(G28>44,"C",IF(G28>34,"D","F")))) -> B
A29: 10 | B29: ='SUB-10'!E11 -> 25241110 | D29: =SCHEME!F27 -> Language Lab | F29: =SCHEME!M27 -> 100 | G29: =IFERROR(VLOOKUP($C$15,'FINAL SHEET'!$E$15:$T$114,11,FALSE()),"Not Found") -> 97 | H29: 1 | I29: =IFERROR(VLOOKUP(C15,'SUB-10'!E16:J115,6,FALSE()),"Not Found") -> 1 | J29: =IF(G29>89,"A",IF(G29>59,"B",IF(G29>44,"C",IF(G29>34,"D","F")))) -> A
A30: 11 | B30: ='SUB- NEC'!E11 -> NECXXXXX | D30: =SCHEME!F28 -> Novel Engaging Course | F30: =SCHEME!M28 -> 50 | G30: =IFERROR(VLOOKUP($C$15,'FINAL SHEET'!$E$15:$T$114,12,FALSE()),"Not Found") -> 46 | H30: 1 | I30: =IFERROR(VLOOKUP(C15,'SUB- NEC'!E16:J115,6,FALSE()),"Not Found") -> 1 | J30: =IF(G30>39,"A",IF(G30>29,"B",IF(G30>19,"C",IF(G30>15,"D","F")))) -> A
B32: TOTAL | F32: 1000 | G32: =SUM(G20:G30) -> 827 | H32: =SUM(H20:H30) -> 20 | I32: =I20+I21+I22+I23+I24+I25+I26+I27+I28+I29+I30 -> 19 | J32: =IFERROR(VLOOKUP(C15,'FINAL SHEET'!E15:T114,16,FALSE()),"Not Found") -> PASS
A34: 12 | B34: ='SUB-12'!E11 -> 25241112 | D34: =SCHEME!F30 -> Universal Human Values & Professional Ethics (UHVPE) | F34: 100 | G34: =IFERROR(VLOOKUP(C15,'SUB-12'!E15:N114,8,FALSE()),"Not Found") -> 96 | H34: =IFERROR(VLOOKUP(C15,'SUB-12'!E15:N114,9,FALSE()),"Not Found") -> 3 | I34: 3 | J34: =IF(G34>89,"A",IF(G34>59,"B",IF(G34>44,"C",IF(G34>34,"D","F")))) -> A
H37: =J32 -> PASS
A40: GRADING: | C40: A | E40: B | F40: C | G40: D | I40: F
C41: 100 - 90 | E41: 89-60 | F41: 59-45 | G41: 44-35 | I41: BELOW 35

Sheet FINAL SHEET
D2: माधव प्रौद्योगिकी एवं विज्ञान संस्थान, ग्वालियर (म.प्र.), भारत
D4: Madhav Institute of Technology & Science DU, Gwalior (M.P.), INDIA
D5: Deemed University
D6: (Declared under Distinct Category by Ministry of Education, Government of India)
G7: NAAC ACCREDITED WITH A++ GRADE
D8: Department of Engineering Mathematics & Computing
D9: B. Tech. I Semester (MAC)
D12: S.No | E12: ENROLLMENT NO. | F12: SUB 1 | G12: SUB 2 | H12: SUB 3 | I12: SUB 4 | J12: SUB 5 | K12: SUB 6 | L12: SUB 7 | M12: SUB 8 | N12: SUB 9 | O12: SUB 10 | P12: SUB 11 | Q12: Total | R12: Pass % | S12: CREDIT | T12: Result
F13: 100 | G13: 100 | H13: 100 | I13: 100 | J13: 100 | K13: 100 | L13: 100 | M13: 50 | N13: 100 | O13: 100 | P13: 50 | Q13: =P13+O13+N13+M13+L13+K13+J13+I13+H13+G13+F13 -> 1000 | R13: % | S13: 20 | T13: PASS/FAIL
V14: NUMBER OF STUDENTS THAT PASSED :
D15: ='SUB-1'!D15 -> 1 | E15: ='SUB-1'!E15 -> BTMC24O1001 | F15: ='SUB-1'!L15 -> 60 | G15: ='SUB- 2'!K15 -> 62 | H15: ='SUB-3'!L15 -> 38 | I15: ='SUB-4'!L15 -> 47 | J15: ='SUB-5'!L15 -> 49 | K15: ='SUB-6'!H16 -> 66 | L15: ='SUB-7'!H16 -> 67 | M15: ='SUB-8'!H16 -> 32 | N15: ='SUB-9'!H17 -> 30 | O15: ='SUB-10'!H16 -> 14 | P15: ='SUB- NEC'!G16 -> 30 | Q15: =SUM(F15:P15) -> 495 | R15: =(Q15/1000)*100 -> 49.5 | S15: =('SUB-1'!M15)+('SUB- 2'!L15)+('SUB-3'!M15)+('SUB-4'!M15)+('SUB-5'!M15)+('SUB-6'!J16)+('SUB-7'!J16)+('SUB-8'!J16)+('SUB-9'!J17)+('SUB-10'!J16)+('SUB- NEC'!J16) -> 11 | T15: =IF(R15<40,"FAIL","PASS") -> PASS | V15: =COUNTIF(T15:T114,"PASS") -> 91
D16: ='SUB-1'!D16 -> 2 | E16: ='SUB-1'!E16 -> BTMC24O1002 | F16: ='SUB-1'!L16 -> 26 | G16: ='SUB- 2'!K16 -> 56 | H16: ='SUB-3'!L16 -> 39 | I16: ='SUB-4'!L16 -> 14 | J16: ='SUB-5'!L16 -> 55 | K16: ='SUB-6'!H17 -> 30 | L16: ='SUB-7'!H17 -> 77 | M16: ='SUB-8'!H17 -> 48 | N16: ='SUB-9'!H18 -> 42 | O16: ='SUB-10'!H17 -> 73 | P16: ='SUB- NEC'!G17 -> 14 | Q16: =SUM(F16:P16) -> 474 | R16: =(Q16/1000)*100 -> 47.4 | S16: =('SUB-1'!M16)+('SUB- 2'!L16)+('SUB-3'!M16)+('SUB-4'!M16)+('SUB-5'!M16)+('SUB-6'!J17)+('SUB-7'!J17)+('SUB-8'!J17)+('SUB-9'!J18)+('SUB-10'!J17)+('SUB- NEC'!J17) -> 9 | T16: =IF(R16<40,"FAIL","PASS") -> PASS
D17: ='SUB-1'!D17 -> 3 | E17: ='SUB-1'!E17 -> BTMC24O1003 | F17: ='SUB-1'!L17 -> 44 | G17: ='SUB- 2'!K17 -> 45 | H17: ='SUB-3'!L17 -> 32 | I17: ='SUB-4'!L17 -> 36 | J17: ='SUB-5'!L17 -> 64 | K17: ='SUB-6'!H18 -> 66 | L17: ='SUB-7'!H18 -> 34 | M17: ='SUB-8'!H18 -> 22 | N17: ='SUB-9'!H19 -> 28 | O17: ='SUB-10'!H18 -> 23 | P17: ='SUB- NEC'!G18 -> 37 | Q17: =SUM(F17:P17) -> 431 | R17: =(Q17/1000)*100 -> 43.1 | S17: =('SUB-1'!M17)+('SUB- 2'!L17)+('SUB-3'!M17)+('SUB-4'!M17)+('SUB-5'!M17)+('SUB-6'!J18)+('SUB-7'!J18)+('SUB-8'!J18)+('SUB-9'!J19)+('SUB-10'!J18)+('SUB- NEC'!J18) -> 8 | T17: =IF(R17<40,"FAIL","PASS") -> PASS | V17: NUMBER OF STUDENTS THAT FAILED :
D18: ='SUB-1'!D18 -> 4 | E18: ='SUB-1'!E18 -> BTMC24O1004 | F18: ='SUB-1'!L18 -> 57 | G18: ='SUB- 2'!K18 -> 43 | H18: ='SUB-3'!L18 -> 69 | I18: ='SUB-4'!L18 -> 62 | J18: ='SUB-5'!L18 -> 43 | K18: ='SUB-6'!H19 -> 70 | L18: ='SUB-7'!H19 -> 35 | M18: ='SUB-8'!H19 -> 6 | N18: ='SUB-9'!H20 -> 60 | O18: ='SUB-10'!H19 -> 88 | P18: ='SUB- NEC'!G19 -> 48 | Q18: =SUM(F18:P18) -> 581 | R18: =(Q18/1000)*100 -> 58.1 | S18: =('SUB-1'!M18)+('SUB- 2'!L18)+('SUB-3'!M18)+('SUB-4'!M18)+('SUB-5'!M18)+('SUB-6'!J19)+('SUB-7'!J19)+('SUB-8'!J19)+('SUB-9'!J20)+('SUB-10'!J19)+('SUB- NEC'!J19) -> 13 | T18: =IF(R18<40,"FAIL","PASS") -> PASS | V18: =COUNTIF(T15:T114,"FAIL") -> 9
D19: ='SUB-1'!D19 -> 5 | E19: ='SUB-1'!E19 -> BTMC24O1005 | F19: ='SUB-1'!L19 -> 54 | G19: ='SUB- 2'!K19 -> 47 | H19: ='SUB-3'!L19 -> 33 | I19: ='SUB-4'!L19 -> 35 | J19: ='SUB-5'!L19 -> 51 | K19: ='SUB-6'!H20 -> 41 | L19: ='SUB-7'!H20 -> 38 | M19: ='SUB-8'!H20 -> 42 | N19: ='SUB-9'!H21 -> 88 | O19: ='SUB-10'!H20 -> 78 | P19: ='SUB- NEC'!G20 -> 3 | Q19: =SUM(F19:P19) -> 510 | R19: =(Q19/1000)*100 -> 51 | S19: =('SUB-1'!M19)+('SUB- 2'!L19)+('SUB-3'!M19)+('SUB-4'!M19)+('SUB-5'!M19)+('SUB-6'!J20)+('SUB-7'!J20)+('SUB-8'!J20)+('SUB-9'!J21)+('SUB-10'!J20)+('SUB- NEC'!J20) -> 10 | T19: =IF(R19<40,"FAIL","PASS") -> PASS
D20: ='SUB-1'!D20 -> 6 | E20: ='SUB-1'!E20 -> BTMC24O1006 | F20: ='SUB-1'!L20 -> 42 | G20: ='SUB- 2'!K20 -> 56 | H20: ='SUB-3'!L20 -> 49 | I20: ='SUB-4'!L20 -> 57 | J20: ='SUB-5'!L20 -> 65 | K20: ='SUB-6'!H21 -> 27 | L20: ='SUB-7'!H21 -> 58 | M20: ='SUB-8'!H21 -> 31 | N20: ='SUB-9'!H22 -> 50 | O20: ='SUB-10'!H21 -> 31 | P20: ='SUB- NEC'!G21 -> 49 | Q20: =SUM(F20:P20) -> 515 | R20: =(Q20/1000)*100 -> 51.5 | S20: =('SUB-1'!M20)+('SUB- 2'!L20)+('SUB-3'!M20)+('SUB-4'!M20)+('SUB-5'!M20)+('SUB-6'!J21)+('SUB-7'!J21)+('SUB-8'!J21)+('SUB-9'!J22)+('SUB-10'!J21)+('SUB- NEC'!J21) -> 12 | T20: =IF(R20<40,"FAIL","PASS") -> PASS
D21: ='SUB-1'!D21 -> 7 | E21: ='SUB-1'!E21 -> BTMC24O1007 | F21: ='SUB-1'!L21 -> 57 | G21: ='SUB- 2'!K21 -> 44 | H21: ='SUB-3'!L21 -> 39 | I21: ='SUB-4'!L21 -> 55 | J21: ='SUB-5'!L21 -> 64 | K21: ='SUB-6'!H22 -> 53 | L21: ='SUB-7'!H22 -> 77 | M21: ='SUB-8'!H22 -> 1 | N21: ='SUB-9'!H23 -> 82 | O21: ='SUB-10'!H22 -> 21 | P21: ='SUB- NEC'!G22 -> 40 | Q21: =SUM(F21:P21) -> 533 | R21: =(Q21/1000)*100 -> 53.3 | S21: =('SUB-1'!M21)+('SUB- 2'!L21)+('SUB-3'!M21)+('SUB-4'!M21)+('SUB-5'!M21)+('SUB-6'!J22)+('SUB-7'!J22)+('SUB-8'!J22)+('SUB-9'!J23)+('SUB-10'!J22)+('SUB- NEC'!J22) -> 12 | T21: =IF(R21<40,"FAIL","PASS") -> PASS
D22: ='SUB-1'!D22 -> 8 | E22: ='SUB-1'!E22 -> BTMC24O1008 | F22: ='SUB-1'!L22 -> 43 | G22: ='SUB- 2'!K22 -> 40 | H22: ='SUB-3'!L22 -> 51 | I22: ='SUB-4'!L22 -> 39 | J22: ='SUB-5'!L22 -> 46 | K22: ='SUB-6'!H23 -> 11 | L22: ='SUB-7'!H23 -> 24 | M22: ='SUB-8'!H23 -> 28 | N22: ='SUB-9'!H24 -> 52 | O22: ='SUB-10'!H23 -> 45 | P22: ='SUB- NEC'!G23 -> 1 | Q22: =SUM(F22:P22) -> 380 | R22: =(Q22/1000)*100 -> 38 | S22: =('SUB-1'!M22)+('SUB- 2'!L22)+('SUB-3'!M22)+('SUB-4'!M22)+('SUB-5'!M22)+('SUB-6'!J23)+('SUB-7'!J23)+('SUB-8'!J23)+('SUB-9'!J24)+('SUB-10'!J23)+('SUB- NEC'!J23) -> 9 | T22: =IF(R22<40,"FAIL","PASS") -> FAIL
D23: ='SUB-1'!D23 -> 9 | E23: ='SUB-1'!E23 -> BTMC24O1009 | F23: ='SUB-1'!L23 -> 70 | G23: ='SUB- 2'!K23 -> 57 | H23: ='SUB-3'!L23 -> 51 | I23: ='SUB-4'!L23 -> 63 | J23: ='SUB-5'!L23 -> 27 | K23: ='SUB-6'!H24 -> 72 | L23: ='SUB-7'!H24 -> 32 | M23: ='SUB-8'!H24 -> 19 | N23: ='SUB-9'!H25 -> 74 | O23: ='SUB-10'!H24 -> 44 | P23: ='SUB- NEC'!G24 -> 7 | Q23: =SUM(F23:P23) -> 516 | R23: =(Q23/1000)*100 -> 51.6 | S23: =('SUB-1'!M23)+('SUB- 2'!L23)+('SUB-3'!M23)+('SUB-4'!M23)+('SUB-5'!M23)+('SUB-6'!J24)+('SUB-7'!J24)+('SUB-8'!J24)+('SUB-9'!J25)+('SUB-10'!J24)+('SUB- NEC'!J24) -> 12 | T23: =IF(R23<40,"FAIL","PASS") -> PASS
D24: ='SUB-1'!D24 -> 10 | E24: ='SUB-1'!E24 -> BTMC24O1010 | F24: ='SUB-1'!L24 -> 53 | G24: ='SUB- 2'!K24 -> 47 | H24: ='SUB-3'!L24 -> 36 | I24: ='SUB-4'!L24 -> 29 | J24: ='SUB-5'!L24 -> 51 | K24: ='SUB-6'!H25 -> 60 | L24: ='SUB-7'!H25 -> 92 | M24: ='SUB-8'!H25 -> 23 | N24: ='SUB-9'!H26 -> 24 | O24: ='SUB-10'!H25 -> 70 | P24: ='SUB- NEC'!G25 -> 7 | Q24: =SUM(F24:P24) -> 492 | R24: =(Q24/1000)*100 -> 49.2 | S24: =('SUB-1'!M24)+('SUB- 2'!L24)+('SUB-3'!M24)+('SUB-4'!M24)+('SUB-5'!M24)+('SUB-6'!J25)+('SUB-7'!J25)+('SUB-8'!J25)+('SUB-9'!J26)+('SUB-10'!J25)+('SUB- NEC'!J25) -> 10 | T24: =IF(R24<40,"FAIL","PASS") -> PASS
D25: ='SUB-1'!D25 -> 11 | E25: ='SUB-1'!E25 -> BTMC24O1011 | F25: ='SUB-1'!L25 -> 33 | G25: ='SUB- 2'!K25 -> 46 | H25: ='SUB-3'!L25 -> 65 | I25: ='SUB-4'!L25 -> 35 | J25: ='SUB-5'!L25 -> 67 | K25: ='SUB-6'!H26 -> 14 | L25: ='SUB-7'!H26 -> 85 | M25: ='SUB-8'!H26 -> 34 | N25: ='SUB-9'!H27 -> 20 | O25: ='SUB-10'!H26 -> 22 | P25: ='SUB- NEC'!G26 -> 46 | Q25: =SUM(F25:P25) -> 467 | R25: =(Q25/1000)*100 -> 46.7 | S25: =('SUB-1'!M25)+('SUB- 2'!L25)+('SUB-3'!M25)+('SUB-4'!M25)+('SUB-5'!M25)+('SUB-6'!J26)+('SUB-7'!J26)+('SUB-8'!J26)+('SUB-9'!J27)+('SUB-10'!J26)+('SUB- NEC'!J26) -> 8 | T25: =IF(R25<40,"FAIL","PASS") -> PASS
D26: ='SUB-1'!D26 -> 12 | E26: ='SUB-1'!E26 -> BTMC24O1012 | F26: ='SUB-1'!L26 -> 27 | G26: ='SUB- 2'!K26 -> 36 | H26: ='SUB-3'!L26 -> 37 | I26: ='SUB-4'!L26 -> 41 | J26: ='SUB-5'!L26 -> 44 | K26: ='SUB-6'!H27 -> 51 | L26: ='SUB-7'!H27 -> 2 | M26: ='SUB-8'!H27 -> 1 | N26: ='SUB-9'!H28 -> 82 | O26: ='SUB-10'!H27 -> 34 | P26: ='SUB- NEC'!G27 -> 19 | Q26: =SUM(F26:P26) -> 374 | R26: =(Q26/1000)*100 -> 37.4 | S26: =('SUB-1'!M26)+('SUB- 2'!L26)+('SUB-3'!M26)+('SUB-4'!M26)+('SUB-5'!M26)+('SUB-6'!J27)+('SUB-7'!J27)+('SUB-8'!J27)+('SUB-9'!J28)+('SUB-10'!J27)+('SUB- NEC'!J27) -> 7 | T26: =IF(R26<40,"FAIL","PASS") -> FAIL
D27: ='SUB-1'!D27 -> 13 | E27: ='SUB-1'!E27 -> BTMC24O1013 | F27: ='SUB-1'!L27 -> 40 | G27: ='SUB- 2'!K27 -> 45 | H27: ='SUB-3'!L27 -> 58 | I27: ='SUB-4'!L27 -> 67 | J27: ='SUB-5'!L27 -> 59 | K27: ='SUB-6'!H28 -> 76 | L27: ='SUB-7'!H28 -> 42 | M27: ='SUB-8'!H28 -> 12 | N27: ='SUB-9'!H29 -> 63 | O27: ='SUB-10'!H28 -> 38 | P27: ='SUB- NEC'!G28 -> 6 | Q27: =SUM(F27:P27) -> 506 | R27: =(Q27/1000)*100 -> 50.6 | S27: =('SUB-1'!M27)+('SUB- 2'!L27)+('SUB-3'!M27)+('SUB-4'!M27)+('SUB-5'!M27)+('SUB-6'!J28)+('SUB-7'!J28)+('SUB-8'!J28)+('SUB-9'!J29)+('SUB-10'!J28)+('SUB- NEC'!J28) -> 12 | T27: =IF(R27<40,"FAIL","PASS") -> PASS
D28: ='SUB-1'!D28 -> 14 | E28: ='SUB-1'!E28 -> BTMC24O1014 | F28: ='SUB-1'!L28 -> 48 | G28: ='SUB- 2'!K28 -> 44 | H28: ='SUB-3'!L28 -> 71 | I28: ='SUB-4'!L28 -> 73 | J28: ='SUB-5'!L28 -> 34 | K28: ='SUB-6'!H29 -> 25 | L28: ='SUB-7'!H29 -> 6 | M28: ='SUB-8'!H29 -> 34 | N28: ='SUB-9'!H30 -> 50 | O28: ='SUB-10'!H29 -> 40 | P28: ='SUB- NEC'!G29 -> 10 | Q28: =SUM(F28:P28) -> 435 | R28: =(Q28/1000)*100 -> 43.5 | S28: =('SUB-1'!M28)+('SUB- 2'!L28)+('SUB-3'!M28)+('SUB-4'!M28)+('SUB-5'!M28)+('SUB-6'!J29)+('SUB-7'!J29)+('SUB-8'!J29)+('SUB-9'!J30)+('SUB-10'!J29)+('SUB- NEC'!J29) -> 9 | T28: =IF(R28<40,"FAIL","PASS") -> PASS
D29: ='SUB-1'!D29 -> 15 | E29: ='SUB-1'!E29 -> BTMC24O1015 | F29: ='SUB-1'!L29 -> 33 | G29: ='SUB- 2'!K29 -> 72 | H29: ='SUB-3'!L29 -> 36 | I29: ='SUB-4'!L29 -> 36 | J29: ='SUB-5'!L29 -> 50 | K29: ='SUB-6'!H30 -> 64 | L29: ='SUB-7'!H30 -> 84 | M29: ='SUB-8'!H30 -> 24 | N29: ='SUB-9'!H31 -> 58 | O29: ='SUB-10'!H30 -> 47 | P29: ='SUB- NEC'!G30 -> 47 | Q29: =SUM(F29:P29) -> 551 | R29: =(Q29/1000)*100 -> 55.1 | S29: =('SUB-1'!M29)+('SUB- 2'!L29)+('SUB-3'!M29)+('SUB-4'!M29)+('SUB-5'!M29)+('SUB-6'!J30)+('SUB-7'!J30)+('SUB-8'!J30)+('SUB-9'!J31)+('SUB-10'!J30)+('SUB- NEC'!J30) -> 11 | T29: =IF(R29<40,"FAIL","PASS") -> PASS
D30: ='SUB-1'!D30 -> 16 | E30: ='SUB-1'!E30 -> BTMC24O1016 | F30: ='SUB-1'!L30 -> 37 | G30: ='SUB- 2'!K30 -> 63 | H30: ='SUB-3'!L30 -> 59 | I30: ='SUB-4'!L30 -> 52 | J30: ='SUB-5'!L30 -> 63 | K30: ='SUB-6'!H31 -> 77 | L30: ='SUB-7'!H31 -> 57 | M30: ='SUB-8'!H31 -> 33 | N30: ='SUB-9'!H32 -> 93 | O30: ='SUB-10'!H31 -> 79 | P30: ='SUB- NEC'!G31 -> 38 | Q30: =SUM(F30:P30) -> 651 | R30: =(Q30/1000)*100 -> 65.1 | S30: =('SUB-1'!M30)+('SUB- 2'!L30)+('SUB-3'!M30)+('SUB-4'!M30)+('SUB-5'!M30)+('SUB-6'!J31)+('SUB-7'!J31)+('SUB-8'!J31)+('SUB-9'!J32)+('SUB-10'!J31)+('SUB- NEC'!J31) -> 15 | T30: =IF(R30<40,"FAIL","PASS") -> PASS
... D114: ='SUB-1'!D114 -> 100 | E114: ='SUB-1'!E114 -> BTMC24O1100 | F114: ='SUB-1'!L114 -> 28 | G114: ='SUB- 2'!K114 -> 55 | H114: ='SUB-3'!L114 -> 66 | I114: ='SUB-4'!L114 -> 36 | J114: ='SUB-5'!L114 -> 58 | K114: ='SUB-6'!H115 -> 39 | L114: ='SUB-7'!H115 -> 95 | M114: ='SUB-8'!H115 -> 34 | N114: ='SUB-9'!H116 -> 26 | O114: ='SUB-10'!H115 -> 79 | P114: ='SUB- NEC'!G115 -> 27 | Q114: =SUM(F114:P114) -> 543 | R114: =(Q114/1000)*100 -> 54.3 | S114: =('SUB-1'!M114)+('SUB- 2'!L114)+('SUB-3'!M114)+('SUB-4'!M114)+('SUB-5'!M114)+('SUB-6'!J115)+('SUB-7'!J115)+('SUB-8'!J115)+('SUB-9'!J116)+('SUB-10'!J115)+('SUB- NEC'!J115) -> 12 | T114: =IF(R114<40,"FAIL","PASS") -> PASS

Sheet STUDENT INFO
A2: माधव प्रौद्योगिकी एवं विज्ञान संस्थान, ग्वालियर (म.प्र.), भारत
A4: Madhav Institute of Technology & Science DU, Gwalior (M.P.), INDIA
A5: Deemed University
A6: (Declared under Distinct Category by Ministry of Education, Government of India)
A7: NAAC ACCREDITED WITH A++ GRADE
A8: Department of Engineering Mathematics & Computing
A9: B. Tech. I Semester (MAC)
B13: S.NO. | C13: ENROLLMENT NO. | F13: EMAIL ADDRESS | I13: STUDENT NAME | L13: FATHER'S NAME | O13: MOTHER'S NAME | R13: D.O.B. | T13: COURSE | U13: BRANCH
B15: 1 | C15: BTMC24O1001 | F15: 24mc10aa1@mitsgwl.ac.in | I15: AASTHA PYASI | L15: NARENDRA PYASI | O15: ARCHNA PYASI | R15: 38546 | T15: B.Tech. | U15: Mathematics and Computing
B16: 2 | C16: BTMC24O1002 | F16: 24mc10ab2@mitsgwl.ac.in | I16: ABHAY PRATAP SINGH YADAV | L16: SUKHENDRA SINGH YADAV | O16: REKHA YADAV | R16: 38547 | T16: B.Tech. | U16: Mathematics and Computing
B17: 3 | C17: BTMC24O1003 | F17: 24mc10ab3@mitsgwl.ac.in | I17: ABHAY SHARMA | L17: MR UTTAM NARAYAN SHARMA | O17: MRS NEELMA SHARMA | R17: 38548 | T17: B.Tech. | U17: Mathematics and Computing
B18: 4 | C18: BTMC24O1004 | F18: a9893414501@gmail.com | I18: ABHI JAIN | L18: ARUN KUMAR JAIN | O18: VINITA JAIN | R18: 38549 | T18: B.Tech. | U18: Mathematics and Computing
B19: 5 | C19: BTMC24O1005 | F19: 24mc10ab5@mitsgwl.ac.in | I19: ABHI KACHHWAHA | L19: VINOD KACHHWAHA | O19: MEERA KACHHWAHA | R19: 38550 | T19: B.Tech. | U19: Mathematics and Computing
B20: 6 | C20: BTMC24O1006 | F20: apal98332@gmail.com | I20: ABHISHEK PAL | L20: NAVAL SINGH | O20: URMILA PAL | R20: 38551 | T20: B.Tech. | U20: Mathematics and Computing
B21: 7 | C21: BTMC24O1007 | F21: 24mc10ab8@mitsgwl.ac.in | I21: ABHISHEK YADAV | L21: MANOJ YADAV | O21: ANITA YADAV | R21: 38552 | T21: B.Tech. | U21: Mathematics and Computing
B22: 8 | C22: BTMC24O1008 | F22: 24mc10ad9@mitsgwl.ac.in | I22: ADARSH MISHRA | L22: RAKESH MISHRA | O22: PRABHA MISHRA | R22: 38553 | T22: B.Tech. | U22: Mathematics and Computing
B23: 9 | C23: BTMC24O1009 | F23: 24mc10ad10@mitsgwl.ac.in | I23: ADARSH SONI | L23: BHARAT BHUSHAN SONI | O23: SUNEETA SONI | R23: 38554 | T23: B.Tech. | U23: Mathematics and Computing
B24: 10 | C24: BTMC24O1010 | F24: 24mc10ad10@mitsgwl.ac.in | I24: ADWIT SINGH | L24: BHARAT SINGH | O24: LELIA SINGH | R24: 38555 | T24: B.Tech. | U24: Mathematics and Computing
B25: 11 | C25: BTMC24O1011 | F25: sonid45678@gmail.com | I25: ADITI GUPTA | L25: SANJAY GUPTA | O25: JULI GUPTA | R25: 38556 | T25: B.Tech. | U25: Mathematics and Computing
B26: 12 | C26: BTMC24O1012 | F26: 24mc10ad12@mitsgwl.ac.in | I26: ADITI JAIN | L26: PANKAJ JAIN | O26: RAKHI JAIN | R26: 38557 | T26: B.Tech. | U26: Mathematics and Computing
... B114: 100 | C114: BTMC24O1100 | F114: 24mc1Ori110@mitsgwl.ac.in | I114: RISHABH SINGH | L114: NAROTTAM SINGH | O114: RADHA DEVI | R114: 38645 | T114: B.Tech. | U114: Mathematics and Computing

Sheet SCHEME
D2: माधव प्रौद्योगिकी एवं विज्ञान संस्थान, ग्वालियर (म.प्र.), भारत
D4: Madhav Institute of Technology & Science DU, Gwalior (M.P.), INDIA
D5: Deemed University
D6: (Declared under Distinct Category by Ministry of Education, Government of India)
G7: NAAC ACCREDITED WITH A++ GRADE
D8: Department of Engineering Mathematics & Computing
D9: B. Tech. I Semester (MAC)
A11: SCHEME
D13: S.NO | E13: COURSE CODE | F13: COURSE NAME | G13: Maximum Marks Allotted | M13: Total Marks | N13: Total Credits
G14: THEORY BLOCK | K14: Practical Block
G15: CONTINOUS EVALUATION | K15: Continuous Evaluation
G16: MINOR EVALUATION 1 | H16: MINOR EVALUATION 2 | I16: QUIZ/ ASSIGMENT | J16: MAJOR EVALUATION | K16: Lab Work | L16: Major Evaluation
D18: 1 | E18: 25241101 | F18: Introduction to Computing | G18: 20 | H18: 20 | I18: 30 | J18: 30 | K18: - | L18: - | M18: =SUM(G18:L18) -> 100 | N18: 3
D19: 2 | E19: 25241102 | F19: Computer Programming | G19: 20 | H19: 20 | I19: 30 | J19: 30 | K19: - | L19: - | M19: =SUM(G19:L19) -> 100 | N19: 2
D20: 3 | E20: 25241103 | F20: Advanced Calculus | G20: 20 | H20: 20 | I20: 30 | J20: 30 | K20: - | L20: - | M20: =SUM(G20:L20) -> 100 | N20: 3
D21: 4 | E21: 25241104 | F21: Digital Logic Design | G21: 20 | H21: 20 | I21: 30 | J21: 30 | K21: - | L21: - | M21: =SUM(G21:L21) -> 100 | N21: 3
D22: 5 | E22: 25241105 | F22: Differential Equations | G22: 20 | H22: 20 | I22: 30 | J22: 30 | K22: - | L22: - | M22: =SUM(G22:L22) -> 100 | N22: 3
D23: 6 | E23: 25241106 | F23: Computer Programming Lab | G23: - | H23: - | I23: - | J23: - | K23: 70 | L23: 30 | M23: =SUM(G23:L23) -> 100 | N23: 1
D24: 7 | E24: 25241107 | F24: Computing Lab for Data Analysis | G24: - | H24: - | I24: - | J24: - | K24: 70 | L24: 30 | M24: =SUM(G24:L24) -> 100 | N24: 1
D25: 8 | E25: 25241108 | F25: Semester Proficiency | G25: - | H25: - | I25: - | J25: - | K25: 50 | L25: - | M25: =SUM(G25:L25) -> 50 | N25: 1
D26: 9 | E26: 25241109 | F26: Micro Project-1 | G26: - | H26: - | I26: - | J26: - | K26: 70 | L26: 30 | M26: =SUM(G26:L26) -> 100 | N26: 1
D27: 10 | E27: 25241110 | F27: Language Lab | G27: - | H27: - | I27: - | J27: - | K27: 70 | L27: 30 | M27: =SUM(G27:L27) -> 100 | N27: 1
D28: 11 | E28: NECXXXX | F28: Novel Engaging Course | G28: - | H28: - | I28: - | J28: - | K28: - | L28: 50 | M28: =SUM(G28:L28) -> 50 | N28: 1
D29: TOTAL | G29: =SUM(G18:G28) -> 100 | H29: =SUM(H18:H28) -> 100 | I29: =SUM(I18:I28) -> 150 | J29: =SUM(J18:J28) -> 150 | K29: =SUM(K18:K28) -> 330 | L29: =SUM(L18:L28) -> 170 | M29: =SUM(M18:M28) -> 1000 | N29: =SUM(N18:N28) -> 20
D30: 12 | E30: 25241111 | F30: Universal Human Values & Professional Ethics (UHVPE) | G30: 20 | H30: 20 | I30: 30 | J30: 30 | M30: 100 | N30: GRADE

Sheet SUB-1
D2: माधव प्रौद्योगिकी एवं विज्ञान संस्थान, ग्वालियर (म.प्र.), भारत
D4: Madhav Institute of Technology & Science DU, Gwalior (M.P.), INDIA
D5: Deemed University
D6: (Declared under Distinct Category by Ministry of Education, Government of India)
G7: NAAC ACCREDITED WITH A++ GRADE
D8: Department of Engineering Mathematics & Computing
D9: B. Tech. I Semester (MAC)
E11: 25241101 | F11: DC | H11: INTRODUCTION TO C0MPUTING
D12: S.No | E12: ENROLLMENT NO. | F12: Minor-1 | G12: Minor-2 | H12: Quiz | I12: Assignment | J12: Quiz+Assignment | K12: Major | L12: Total | M12: CREDIT | N12: Result
F13: 20 | G13: 20 | H13: 10 | I13: 20 | J13: 30 | K13: 30 | L13: 100 | M13: 3 | N13: PASS/FAIL
D15: 1 | E15: BTMC24O1001 | F15: 1 | G15: 20 | H15: 10 | I15: 20 | J15: =H15+I15 -> 30 | K15: 9 | L15: =F15+G15+J15+K15 -> 60 | M15: =IF(L15>75,3,IF(L15>50,2,IF(L15>35,1,0))) -> 2 | N15: =IF(L15<35,"FAIL","PASS") -> PASS
D16: 2 | E16: BTMC24O1002 | F16: 2 | G16: 11 | H16: 6 | I16: 1 | J16: =H16+I16 -> 7 | K16: 6 | L16: =F16+G16+J16+K16 -> 26 | M16: =IF(L16>75,3,IF(L16>50,2,IF(L16>35,1,0))) -> 0 | N16: =IF(L16<35,"FAIL","PASS") -> FAIL | P16: CLASS OVERVIEW
D17: 3 | E17: BTMC24O1003 | F17: 17 | G17: 13 | H17: 5 | I17: 2 | J17: =H17+I17 -> 7 | K17: 7 | L17: =F17+G17+J17+K17 -> 44 | M17: =IF(L17>75,3,IF(L17>50,2,IF(L17>35,1,0))) -> 1 | N17: =IF(L17<35,"FAIL","PASS") -> PASS | P17: PASSED | Q17: =COUNTIF(N15:N114,"PASS") -> 78
D18: 4 | E18: BTMC24O1004 | F18: 13 | G18: 5 | H18: 1 | I18: 10 | J18: =H18+I18 -> 11 | K18: 28 | L18: =F18+G18+J18+K18 -> 57 | M18: =IF(L18>75,3,IF(L18>50,2,IF(L18>35,1,0))) -> 2 | N18: =IF(L18<35,"FAIL","PASS") -> PASS | P18: FAILED | Q18: =COUNTIF(N15:N114,"FAIL") -> 22
D19: 5 | E19: BTMC24O1005 | F19: 9 | G19: 17 | H19: 8 | I19: 3 | J19: =H19+I19 -> 11 | K19: 17 | L19: =F19+G19+J19+K19 -> 54 | M19: =IF(L19>75,3,IF(L19>50,2,IF(L19>35,1,0))) -> 2 | N19: =IF(L19<35,"FAIL","PASS") -> PASS
D20: 6 | E20: BTMC24O1006 | F20: 13 | G20: 16 | H20: 3 | I20: 1 | J20: =H20+I20 -> 4 | K20: 9 | L20: =F20+G20+J20+K20 -> 42 | M20: =IF(L20>75,3,IF(L20>50,2,IF(L20>35,1,0))) -> 1 | N20: =IF(L20<35,"FAIL","PASS") -> PASS
D21: 7 | E21: BTMC24O1007 | F21: 8 | G21: 6 | H21: 0 | I21: 20 | J21: =H21+I21 -> 20 | K21: 23 | L21: =F21+G21+J21+K21 -> 57 | M21: =IF(L21>75,3,IF(L21>50,2,IF(L21>35,1,0))) -> 2 | N21: =IF(L21<35,"FAIL","PASS") -> PASS
D22: 8 | E22: BTMC24O1008 | F22: 7 | G22: 18 | H22: 0 | I22: 2 | J22: =H22+I22 -> 2 | K22: 16 | L22: =F22+G22+J22+K22 -> 43 | M22: =IF(L22>75,3,IF(L22>50,2,IF(L22>35,1,0))) -> 1 | N22: =IF(L22<35,"FAIL","PASS") -> PASS
D23: 9 | E23: BTMC24O1009 | F23: 14 | G23: 18 | H23: 5 | I23: 16 | J23: =H23+I23 -> 21 | K23: 17 | L23: =F23+G23+J23+K23 -> 70 | M23: =IF(L23>75,3,IF(L23>50,2,IF(L23>35,1,0))) -> 2 | N23: =IF(L23<35,"FAIL","PASS") -> PASS
D24: 10 | E24: BTMC24O1010 | F24: 7 | G24: 13 | H24: 4 | I24: 9 | J24: =H24+I24 -> 13 | K24: 20 | L24: =F24+G24+J24+K24 -> 53 | M24: =IF(L24>75,3,IF(L24>50,2,IF(L24>35,1,0))) -> 2 | N24: =IF(L24<35,"FAIL","PASS") -> PASS
D25: 11 | E25: BTMC24O1011 | F25: 1 | G25: 5 | H25: 5 | I25: 18 | J25: =H25+I25 -> 23 | K25: 4 | L25: =F25+G25+J25+K25 -> 33 | M25: =IF(L25>75,3,IF(L25>50,2,IF(L25>35,1,0))) -> 0 | N25: =IF(L25<35,"FAIL","PASS") -> FAIL
D26: 12 | E26: BTMC24O1012 | F26: 8 | G26: 3 | H26: 10 | I26: 2 | J26: =H26+I26 -> 12 | K26: 4 | L26: =F26+G26+J26+K26 -> 27 | M26: =IF(L26>75,3,IF(L26>50,2,IF(L26>35,1,0))) -> 0 | N26: =IF(L26<35,"FAIL","PASS") -> FAIL
D27: 13 | E27: BTMC24O1013 | F27: 10 | G27: 2 | H27: 2 | I27: 19 | J27: =H27+I27 -> 21 | K27: 7 | L27: =F27+G27+J27+K27 -> 40 | M27: =IF(L27>75,3,IF(L27>50,2,IF(L27>35,1,0))) -> 1 | N27: =IF(L27<35,"FAIL","PASS") -> PASS
D28: 14 | E28: BTMC24O1014 | F28: 17 | G28: 1 | H28: 6 | I28: 15 | J28: =H28+I28 -> 21 | K28: 9 | L28: =F28+G28+J28+K28 -> 48 | M28: =IF(L28>75,3,IF(L28>50,2,IF(L28>35,1,0))) -> 1 | N28: =IF(L28<35,"FAIL","PASS") -> PASS
D29: 15 | E29: BTMC24O1015 | F29: 2 | G29: 12 | H29: 6 | I29: 4 | J29: =H29+I29 -> 10 | K29: 9 | L29: =F29+G29+J29+K29 -> 33 | M29: =IF(L29>75,3,IF(L29>50,2,IF(L29>35,1,0))) -> 0 | N29: =IF(L29<35,"FAIL","PASS") -> FAIL
D30: 16 | E30: BTMC24O1016 | F30: 3 | G30: 7 | H30: 2 | I30: 12 | J30: =H30+I30 -> 14 | K30: 13 | L30: =F30+G30+J30+K30 -> 37 | M30: =IF(L30>75,3,IF(L30>50,2,IF(L30>35,1,0))) -> 1 | N30: =IF(L30<35,"FAIL","PASS") -> PASS
... D77: 63 | E77: BTMC24O1063 | F77: 4 | G77: 10 | H77: 3 | I77: 3 | J77: =H77+I77 -> 6 | K77: 2 | L77: =F77+G77+J77+K77 -> 22 | M77: =IF(L77>75,3,IF(L77>50,2,IF(L77>35,1,0))) -> 0 | N77: =IF(L77<35,"FAIL","PASS") -> FAIL
D78: 64 | E78: BTMC24O1064 | F78: 3 | G78: 1 | H78: 2 | I78: 15 | J78: =H78+I78 -> 17 | K78: 1 | L78: =F78+G78+J78+K78 -> 22 | M78: =IF(L78>75,3,IF(L78>50,2,IF(L78>35,1,0))) -> 0 | N78: FAIL
D79: 65 | E79: BTMC24O1065 | F79: 6 | G79: 2 | H79: 7 | I79: 12 | J79: =H79+I79 -> 19 | K79: 21 | L79: =F79+G79+J79+K79 -> 48 | M79: =IF(L79>75,3,IF(L79>50,2,IF(L79>35,1,0))) -> 1 | N79: =IF(L79<35,"FAIL","PASS") -> PASS
D80: 66 | E80: BTMC24O1066 | F80: 13 | G80: 20 | H80: 7 | I80: 3 | J80: =H80+I80 -> 10 | K80: 10 | L80: =F80+G80+J80+K80 -> 53 | M80: =IF(L80>75,3,IF(L80>50,2,IF(L80>35,1,0))) -> 2 | N80: =IF(L80<35,"FAIL","PASS") -> PASS
D81: 67 | E81: BTMC24O1067 | F81: 13 | G81: 16 | H81: 1 | I81: 0 | J81: =H81+I81 -> 1 | K81: 14 | L81: =F81+G81+J81+K81 -> 44 | M81: =IF(L81>75,3,IF(L81>50,2,IF(L81>35,1,0))) -> 1 | N81: =IF(L81<35,"FAIL","PASS") -> PASS
D82: 68 | E82: BTMC24O1068 | F82: 6 | G82: 12 | H82: 1 | I82: 8 | J82: =H82+I82 -> 9 | K82: 19 | L82: =F82+G82+J82+K82 -> 46 | M82: =IF(L82>75,3,IF(L82>50,2,IF(L82>35,1,0))) -> 1 | N82: =IF(L82<35,"FAIL","PASS") -> PASS
D83: 69 | E83: BTMC24O1069 | F83: 1 | G83: 16 | H83: 2 | I83: 4 | J83: =H83+I83 -> 6 | K83: 22 | L83: =F83+G83+J83+K83 -> 45 | M83: =IF(L83>75,3,IF(L83>50,2,IF(L83>35,1,0))) -> 1 | N83: =IF(L83<35,"FAIL","PASS") -> PASS
D84: 70 | E84: BTMC24O1070 | F84: 7 | G84: 19 | H84: 5 | I84: 12 | J84: =H84+I84 -> 17 | K84: 8 | L84: =F84+G84+J84+K84 -> 51 | M84: =IF(L84>75,3,IF(L84>50,2,IF(L84>35,1,0))) -> 2 | N84: =IF(L84<35,"FAIL","PASS") -> PASS
D85: 71 | E85: BTMC24O1071 | F85: 13 | G85: 8 | H85: 7 | I85: 8 | J85: =H85+I85 -> 15 | K85: 30 | L85: =F85+G85+J85+K85 -> 66 | M85: =IF(L85>75,3,IF(L85>50,2,IF(L85>35,1,0))) -> 2 | N85: =IF(L85<35,"FAIL","PASS") -> PASS
D86: 72 | E86: BTMC24O1072 | F86: 15 | G86: 7 | H86: 2 | I86: 6 | J86: =H86+I86 -> 8 | K86: 18 | L86: =F86+G86+J86+K86 -> 48 | M86: =IF(L86>75,3,IF(L86>50,2,IF(L86>35,1,0))) -> 1 | N86: =IF(L86<35,"FAIL","PASS") -> PASS
D87: 73 | E87: BTMC24O1073 | F87: 13 | G87: 4 | H87: 2 | I87: 1 | J87: =H87+I87 -> 3 | K87: 28 | L87: =F87+G87+J87+K87 -> 48 | M87: =IF(L87>75,3,IF(L87>50,2,IF(L87>35,1,0))) -> 1 | N87: =IF(L87<35,"FAIL","PASS") -> PASS
D88: 74 | E88: BTMC24O1074 | F88: 3 | G88: 17 | H88: 9 | I88: 2 | J88: =H88+I88 -> 11 | K88: 1 | L88: =F88+G88+J88+K88 -> 32 | M88: =IF(L88>75,3,IF(L88>50,2,IF(L88>35,1,0))) -> 0 | N88: =IF(L88<35,"FAIL","PASS") -> FAIL
D89: 75 | E89: BTMC24O1075 | F89: 18 | G89: 17 | H89: 10 | I89: 16 | J89: =H89+I89 -> 26 | K89: 29 | L89: =F89+G89+J89+K89 -> 90 | M89: =IF(L89>75,3,IF(L89>50,2,IF(L89>35,1,0))) -> 3 | N89: =IF(L89<35,"FAIL","PASS") -> PASS
D90: 76 | E90: BTMC24O1076 | F90: 10 | G90: 8 | H90: 1 | I90: 10 | J90: =H90+I90 -> 11 | K90: 19 | L90: =F90+G90+J90+K90 -> 48 | M90: =IF(L90>75,3,IF(L90>50,2,IF(L90>35,1,0))) -> 1 | N90: =IF(L90<35,"FAIL","PASS") -> PASS
...

Sheet SUB- 2
D3: माधव प्रौद्योगिकी एवं विज्ञान संस्थान, ग्वालियर (म.प्र.), भारत
D5: Madhav Institute of Technology & Science DU, Gwalior (M.P.), INDIA
D6: Deemed University
D7: (Declared under Distinct Category by Ministry of Education, Government of India)
G8: NAAC ACCREDITED WITH A++ GRADE
D9: Department of Engineering Mathematics & Computing
D10: B. Tech. I Semester (MAC)
D11: 25241102 | E11: ESC | G11: COMPUTER PROGRAMMING
C12: S.No | D12: ENROLLMENT NO. | E12: Minor-1 | F12: Minor-2 | G12: Quiz | H12: Assignment | I12: Quiz+Assignment | J12: Major | K12: Total | L12: CREDIT | M12: Result
E13: 20 | F13: 20 | G13: 10 | H13: 20 | I13: 30 | J13: 30 | K13: 100 | L13: 2 | M13: PASS/FAIL
C15: 1 | D15: BTMC24O1001 | E15: 4 | F15: 20 | G15: 10 | H15: 1 | I15: =G15+H15 -> 11 | J15: 27 | K15: =J15+I15+F15+E15 -> 62 | L15: =IF(K15>50,2,IF(K15>35,1,0)) -> 2 | M15: =IF(K15<35,"FAIL","PASS") -> PASS | O15: CLASS OVERVIEW
C16: 2 | D16: BTMC24O1002 | E16: 14 | F16: 1 | G16: 0 | H16: 18 | I16: =G16+H16 -> 18 | J16: 23 | K16: =J16+I16+F16+E16 -> 56 | L16: =IF(K16>50,2,IF(K16>35,1,0)) -> 2 | M16: =IF(K16<35,"FAIL","PASS") -> PASS | O16: PASSED | P16: =COUNTIF(M15:M114,"PASS") -> 86
C17: 3 | D17: BTMC24O1003 | E17: 14 | F17: 8 | G17: 10 | H17: 8 | I17: =G17+H17 -> 18 | J17: 5 | K17: =J17+I17+F17+E17 -> 45 | L17: =IF(K17>50,2,IF(K17>35,1,0)) -> 1 | M17: =IF(K17<35,"FAIL","PASS") -> PASS | O17: FAILED | P17: =COUNTIF(M15:M114,"FAIL") -> 14
C18: 4 | D18: BTMC24O1004 | E18: 5 | F18: 8 | G18: 1 | H18: 15 | I18: =G18+H18 -> 16 | J18: 14 | K18: =J18+I18+F18+E18 -> 43 | L18: =IF(K18>50,2,IF(K18>35,1,0)) -> 1 | M18: =IF(K18<35,"FAIL","PASS") -> PASS
C19: 5 | D19: BTMC24O1005 | E19: 1 | F19: 16 | G19: 8 | H19: 20 | I19: =G19+H19 -> 28 | J19: 2 | K19: =J19+I19+F19+E19 -> 47 | L19: =IF(K19>50,2,IF(K19>35,1,0)) -> 1 | M19: =IF(K19<35,"FAIL","PASS") -> PASS
C20: 6 | D20: BTMC24O1006 | E20: 15 | F20: 14 | G20: 5 | H20: 0 | I20: =G20+H20 -> 5 | J20: 22 | K20: =J20+I20+F20+E20 -> 56 | L20: =IF(K20>50,2,IF(K20>35,1,0)) -> 2 | M20: =IF(K20<35,"FAIL","PASS") -> PASS
C21: 7 | D21: BTMC24O1007 | E21: 18 | F21: 3 | G21: 6 | H21: 2 | I21: =G21+H21 -> 8 | J21: 15 | K21: =J21+I21+F21+E21 -> 44 | L21: =IF(K21>50,2,IF(K21>35,1,0)) -> 1 | M21: =IF(K21<35,"FAIL","PASS") -> PASS
C22: 8 | D22: BTMC24O1008 | E22: 8 | F22: 1 | G22: 1 | H22: 3 | I22: =G22+H22 -> 4 | J22: 27 | K22: =J22+I22+F22+E22 -> 40 | L22: =IF(K22>50,2,IF(K22>35,1,0)) -> 1 | M22: =IF(K22<35,"FAIL","PASS") -> PASS
C23: 9 | D23: BTMC24O1009 | E23: 10 | F23: 18 | G23: 7 | H23: 9 | I23: =G23+H23 -> 16 | J23: 13 | K23: =J23+I23+F23+E23 -> 57 | L23: =IF(K23>50,2,IF(K23>35,1,0)) -> 2 | M23: =IF(K23<35,"FAIL","PASS") -> PASS
C24: 10 | D24: BTMC24O1010 | E24: 9 | F24: 13 | G24: 1 | H24: 2 | I24: =G24+H24 -> 3 | J24: 22 | K24: =J24+I24+F24+E24 -> 47 | L24: =IF(K24>50,2,IF(K24>35,1,0)) -> 1 | M24: =IF(K24<35,"FAIL","PASS") -> PASS
C25: 11 | D25: BTMC24O1011 | E25: 19 | F25: 7 | G25: 3 | H25: 10 | I25: =G25+H25 -> 13 | J25: 7 | K25: =J25+I25+F25+E25 -> 46 | L25: =IF(K25>50,2,IF(K25>35,1,0)) -> 1 | M25: =IF(K25<35,"FAIL","PASS") -> PASS
C26: 12 | D26: BTMC24O1012 | E26: 3 | F26: 14 | G26: 1 | H26: 8 | I26: =G26+H26 -> 9 | J26: 10 | K26: =J26+I26+F26+E26 -> 36 | L26: =IF(K26>50,2,IF(K26>35,1,0)) -> 1 | M26: =IF(K26<35,"FAIL","PASS") -> PASS
C27: 13 | D27: BTMC24O1013 | E27: 2 | F27: 8 | G27: 10 | H27: 20 | I27: =G27+H27 -> 30 | J27: 5 | K27: =J27+I27+F27+E27 -> 45 | L27: =IF(K27>50,2,IF(K27>35,1,0)) -> 1 | M27: =IF(K27<35,"FAIL","PASS") -> PASS
C28: 14 | D28: BTMC24O1014 | E28: 11 | F28: 20 | G28: 5 | H28: 2 | I28: =G28+H28 -> 7 | J28: 6 | K28: =J28+I28+F28+E28 -> 44 | L28: =IF(K28>50,2,IF(K28>35,1,0)) -> 1 | M28: =IF(K28<35,"FAIL","PASS") -> PASS
C29: 15 | D29: BTMC24O1015 | E29: 11 | F29: 16 | G29: 5 | H29: 14 | I29: =G29+H29 -> 19 | J29: 26 | K29: =J29+I29+F29+E29 -> 72 | L29: =IF(K29>50,2,IF(K29>35,1,0)) -> 2 | M29: =IF(K29<35,"FAIL","PASS") -> PASS
... C34: 20 | D34: BTMC24O1020 | E34: 6 | F34: 20 | G34: 4 | H34: 5 | I34: =G34+H34 -> 9 | J34: 29 | K34: =J34+I34+F34+E34 -> 64 | L34: =IF(K34>50,2,IF(K34>35,1,0)) -> 2 | M34: =IF(K34<35,"FAIL","PASS") -> PASS
C35: 21 | D35: BTMC24O1021 | E35: 15 | F35: 15 | G35: 8 | H35: 14 | I35: =G35+H35 -> 22 | J35: 25 | K35: =E35+F35+I35+J35 -> 77 | L35: =IF(K35>50,2,IF(K35>35,1,0)) -> 2 | M35: =IF(K35<35,"FAIL","PASS") -> PASS
C36: 22 | D36: BTMC24O1022 | E36: 1 | F36: 12 | G36: 1 | H36: 14 | I36: =G36+H36 -> 15 | J36: 20 | K36: =E36+F36+I36+J36 -> 48 | L36: =IF(K36>50,2,IF(K36>35,1,0)) -> 1 | M36: =IF(K36<35,"FAIL","PASS") -> PASS
C37: 23 | D37: BTMC24O1023 | E37: 19 | F37: 17 | G37: 10 | H37: 19 | I37: =G37+H37 -> 29 | J37: 12 | K37: =E37+F37+I37+J37 -> 77 | L37: =IF(K37>50,2,IF(K37>35,1,0)) -> 2 | M37: =IF(K37<35,"FAIL","PASS") -> PASS
C38: 24 | D38: BTMC24O1024 | E38: 0 | F38: 5 | G38: 4 | H38: 5 | I38: =G38+H38 -> 9 | J38: 13 | K38: =E38+F38+I38+J38 -> 27 | L38: =IF(K38>50,2,IF(K38>35,1,0)) -> 0 | M38: =IF(K38<35,"FAIL","PASS") -> FAIL
C39: 25 | D39: BTMC24O1025 | E39: 11 | F39: 15 | G39: 8 | H39: 10 | I39: =G39+H39 -> 18 | J39: 5 | K39: =E39+F39+I39+J39 -> 49 | L39: =IF(K39>50,2,IF(K39>35,1,0)) -> 1 | M39: =IF(K39<35,"FAIL","PASS") -> PASS
C40: 26 | D40: BTMC24O1026 | E40: 18 | F40: 13 | G40: 0 | H40: 20 | I40: =G40+H40 -> 20 | J40: 27 | K40: =E40+F40+I40+J40 -> 78 | L40: =IF(K40>50,2,IF(K40>35,1,0)) -> 2 | M40: =IF(K40<35,"FAIL","PASS") -> PASS
C41: 27 | D41: BTMC24O1027 | E41: 19 | F41: 9 | G41: 4 | H41: 9 | I41: =G41+H41 -> 13 | J41: 5 | K41: =E41+F41+I41+J41 -> 46 | L41: =IF(K41>50,2,IF(K41>35,1,0)) -> 1 | M41: =IF(K41<35,"FAIL","PASS") -> PASS
C42: 28 | D42: BTMC24O1028 | E42: 17 | F42: 0 | G42: 9 | H42: 1 | I42: =G42+H42 -> 10 | J42: 30 | K42: =E42+F42+I42+J42 -> 57 | L42: =IF(K42>50,2,IF(K42>35,1,0)) -> 2 | M42: =IF(K42<35,"FAIL","PASS") -> PASS
C43: 29 | D43: BTMC24O1029 | E43: 18 | F43: 13 | G43: 8 | H43: 0 | I43: =G43+H43 -> 8 | J43: 10 | K43: =E43+F43+I43+J43 -> 49 | L43: =IF(K43>50,2,IF(K43>35,1,0)) -> 1 | M43: =IF(K43<35,"FAIL","PASS") -> PASS
C44: 30 | D44: BTMC24O1030 | E44: 5 | F44: 16 | G44: 8 | H44: 14 | I44: =G44+H44 -> 22 | J44: 28 | K44: =E44+F44+I44+J44 -> 71 | L44: =IF(K44>50,2,IF(K44>35,1,0)) -> 2 | M44: =IF(K44<35,"FAIL","PASS") -> PASS
C45: 31 | D45: BTMC24O1031 | E45: 0 | F45: 16 | G45: 10 | H45: 1 | I45: =G45+H45 -> 11 | J45: 19 | K45: =E45+F45+I45+J45 -> 46 | L45: =IF(K45>50,2,IF(K45>35,1,0)) -> 1 | M45: =IF(K45<35,"FAIL","PASS") -> PASS
C46: 32 | D46: BTMC24O1032 | E46: 17 | F46: 5 | G46: 8 | H46: 9 | I46: =G46+H46 -> 17 | J46: 16 | K46: =E46+F46+I46+J46 -> 55 | L46: =IF(K46>50,2,IF(K46>35,1,0)) -> 2 | M46: =IF(K46<35,"FAIL","PASS") -> PASS
... C114: 100 | D114: BTMC24O1100 | E114: 11 | F114: 11 | G114: 7 | H114: 19 | I114: =G114+H114 -> 26 | J114: 7 | K114: =E114+F114+I114+J114 -> 55 | L114: =IF(K114>50,2,IF(K114>35,1,0)) -> 2 | M114: =IF(K114<35,"FAIL","PASS") -> PASS

Sheet SUB-3
D2: माधव प्रौद्योगिकी एवं विज्ञान संस्थान, ग्वालियर (म.प्र.), भारत
D4: Madhav Institute of Technology & Science DU, Gwalior (M.P.), INDIA
D5: Deemed University
D6: (Declared under Distinct Category by Ministry of Education, Government of India)
G7: NAAC ACCREDITED WITH A++ GRADE
D8: Department of Engineering Mathematics & Computing
D9: B. Tech. I Semester (MAC)
E11: 25241103 | F11: DC | H11: ADVANCED CALCULAS
D12: S.No | E12: ENROLLMENT NO. | F12: Minor-1 | G12: Minor-2 | H12: Quiz | I12: Assignment | J12: Quiz+Assignment | K12: Major | L12: Total | M12: CREDIT | N12: Result
F13: 20 | G13: 20 | H13: 10 | I13: 20 | J13: 30 | K13: 30 | L13: 100 | M13: 3 | N13: PASS/FAIL
D15: 1 | E15: BTMC24O1001 | F15: 0 | G15: 7 | H15: 1 | I15: 6 | J15: =H15+I15 -> 7 | K15: 24 | L15: =K15+J15+G15+F15 -> 38 | M15: =IF(L15>75,3,IF(L15>50,2,IF(L15>35,1,0))) -> 1 | N15: =IF(L15<35,"FAIL","PASS") -> PASS
D16: 2 | E16: BTMC24O1002 | F16: 18 | G16: 1 | H16: 2 | I16: 17 | J16: =H16+I16 -> 19 | K16: 1 | L16: =K16+J16+G16+F16 -> 39 | M16: =IF(L16>75,3,IF(L16>50,2,IF(L16>35,1,0))) -> 1 | N16: =IF(L16<35,"FAIL","PASS") -> PASS | P16: CLASS OVERVIEW
D17: 3 | E17: BTMC24O1003 | F17: 4 | G17: 13 | H17: 4 | I17: 3 | J17: =H17+I17 -> 7 | K17: 8 | L17: =K17+J17+G17+F17 -> 32 | M17: =IF(L17>75,3,IF(L17>50,2,IF(L17>35,1,0))) -> 0 | N17: =IF(L17<35,"FAIL","PASS") -> FAIL | P17: PASSED : | Q17: =COUNTIF(N15:N114,"PASS") -> 89
D18: 4 | E18: BTMC24O1004 | F18: 14 | G18: 12 | H18: 7 | I18: 14 | J18: =H18+I18 -> 21 | K18: 22 | L18: =K18+J18+G18+F18 -> 69 | M18: =IF(L18>75,3,IF(L18>50,2,IF(L18>35,1,0))) -> 2 | N18: =IF(L18<35,"FAIL","PASS") -> PASS | P18: FAILED : | Q18: =COUNTIF(N15:N114,"FAIL") -> 11
D19: 5 | E19: BTMC24O1005 | F19: 6 | G19: 4 | H19: 3 | I19: 9 | J19: =H19+I19 -> 12 | K19: 11 | L19: =K19+J19+G19+F19 -> 33 | M19: =IF(L19>75,3,IF(L19>50,2,IF(L19>35,1,0))) -> 0 | N19: =IF(L19<35,"FAIL","PASS") -> FAIL
D20: 6 | E20: BTMC24O1006 | F20: 3 | G20: 12 | H20: 7 | I20: 14 | J20: =H20+I20 -> 21 | K20: 13 | L20: =K20+J20+G20+F20 -> 49 | M20: =IF(L20>75,3,IF(L20>50,2,IF(L20>35,1,0))) -> 1 | N20: =IF(L20<35,"FAIL","PASS") -> PASS
D21: 7 | E21: BTMC24O1007 | F21: 2 | G21: 9 | H21: 6 | I21: 9 | J21: =H21+I21 -> 15 | K21: 13 | L21: =K21+J21+G21+F21 -> 39 | M21: =IF(L21>75,3,IF(L21>50,2,IF(L21>35,1,0))) -> 1 | N21: =IF(L21<35,"FAIL","PASS") -> PASS
D22: 8 | E22: BTMC24O1008 | F22: 17 | G22: 13 | H22: 5 | I22: 12 | J22: =H22+I22 -> 17 | K22: 4 | L22: =K22+J22+G22+F22 -> 51 | M22: =IF(L22>75,3,IF(L22>50,2,IF(L22>35,1,0))) -> 2 | N22: =IF(L22<35,"FAIL","PASS") -> PASS
D23: 9 | E23: BTMC24O1009 | F23: 18 | G23: 2 | H23: 7 | I23: 8 | J23: =H23+I23 -> 15 | K23: 16 | L23: =K23+J23+G23+F23 -> 51 | M23: =IF(L23>75,3,IF(L23>50,2,IF(L23>35,1,0))) -> 2 | N23: =IF(L23<35,"FAIL","PASS") -> PASS
D24: 10 | E24: BTMC24O1010 | F24: 16 | G24: 12 | H24: 1 | I24: 0 | J24: =H24+I24 -> 1 | K24: 7 | L24: =K24+J24+G24+F24 -> 36 | M24: =IF(L24>75,3,IF(L24>50,2,IF(L24>35,1,0))) -> 1 | N24: =IF(L24<35,"FAIL","PASS") -> PASS
D25: 11 | E25: BTMC24O1011 | F25: 3 | G25: 20 | H25: 9 | I25: 17 | J25: =H25+I25 -> 26 | K25: 16 | L25: =K25+J25+G25+F25 -> 65 | M25: =IF(L25>75,3,IF(L25>50,2,IF(L25>35,1,0))) -> 2 | N25: =IF(L25<35,"FAIL","PASS") -> PASS
D26: 12 | E26: BTMC24O1012 | F26: 20 | G26: 2 | H26: 0 | I26: 2 | J26: =H26+I26 -> 2 | K26: 13 | L26: =K26+J26+G26+F26 -> 37 | M26: =IF(L26>75,3,IF(L26>50,2,IF(L26>35,1,0))) -> 1 | N26: =IF(L26<35,"FAIL","PASS") -> PASS
D27: 13 | E27: BTMC24O1013 | F27: 9 | G27: 18 | H27: 8 | I27: 16 | J27: =H27+I27 -> 24 | K27: 7 | L27: =K27+J27+G27+F27 -> 58 | M27: =IF(L27>75,3,IF(L27>50,2,IF(L27>35,1,0))) -> 2 | N27: =IF(L27<35,"FAIL","PASS") -> PASS
D28: 14 | E28: BTMC24O1014 | F28: 15 | G28: 5 | H28: 10 | I28: 17 | J28: =H28+I28 -> 27 | K28: 24 | L28: =K28+J28+G28+F28 -> 71 | M28: =IF(L28>75,3,IF(L28>50,2,IF(L28>35,1,0))) -> 2 | N28: =IF(L28<35,"FAIL","PASS") -> PASS
D29: 15 | E29: BTMC24O1015 | F29: 2 | G29: 15 | H29: 4 | I29: 5 | J29: =H29+I29 -> 9 | K29: 10 | L29: =K29+J29+G29+F29 -> 36 | M29: =IF(L29>75,3,IF(L29>50,2,IF(L29>35,1,0))) -> 1 | N29: =IF(L29<35,"FAIL","PASS") -> PASS
D30: 16 | E30: BTMC24O1016 | F30: 11 | G30: 6 | H30: 8 | I30: 14 | J30: =H30+I30 -> 22 | K30: 20 | L30: =K30+J30+G30+F30 -> 59 | M30: =IF(L30>75,3,IF(L30>50,2,IF(L30>35,1,0))) -> 2 | N30: =IF(L30<35,"FAIL","PASS") -> PASS
... D34: 20 | E34: BTMC24O1020 | F34: 3 | G34: 16 | H34: 3 | I34: 8 | J34: =H34+I34 -> 11 | K34: 27 | L34: =K34+J34+G34+F34 -> 57 | M34: =IF(L34>75,3,IF(L34>50,2,IF(L34>35,1,0))) -> 2 | N34: =IF(L34<35,"FAIL","PASS") -> PASS
D35: 21 | E35: BTMC24O1021 | F35: 18 | G35: 19 | H35: 10 | I35: 20 | J35: =I35+H35 -> 30 | K35: 29 | L35: =K35+J35+G35+F35 -> 96 | M35: =IF(L35>75,3,IF(L35>50,2,IF(L35>35,1,0))) -> 3 | N35: =IF(L35<35,"FAIL","PASS") -> PASS
D36: 22 | E36: BTMC24O1022 | F36: 4 | G36: 20 | H36: 10 | I36: 8 | J36: =I36+H36 -> 18 | K36: 5 | L36: =K36+J36+G36+F36 -> 47 | M36: =IF(L36>75,3,IF(L36>50,2,IF(L36>35,1,0))) -> 1 | N36: =IF(L36<35,"FAIL","PASS") -> PASS
D37: 23 | E37: BTMC24O1023 | F37: 14 | G37: 19 | H37: 8 | I37: 16 | J37: =I37+H37 -> 24 | K37: 6 | L37: =K37+J37+G37+F37 -> 63 | M37: =IF(L37>75,3,IF(L37>50,2,IF(L37>35,1,0))) -> 2 | N37: =IF(L37<35,"FAIL","PASS") -> PASS
D38: 24 | E38: BTMC24O1024 | F38: 8 | G38: 16 | H38: 7 | I38: 10 | J38: =I38+H38 -> 17 | K38: 8 | L38: =K38+J38+G38+F38 -> 49 | M38: =IF(L38>75,3,IF(L38>50,2,IF(L38>35,1,0))) -> 1 | N38: =IF(L38<35,"FAIL","PASS") -> PASS
D39: 25 | E39: BTMC24O1025 | F39: 8 | G39: 2 | H39: 10 | I39: 17 | J39: =I39+H39 -> 27 | K39: 1 | L39: =K39+J39+G39+F39 -> 38 | M39: =IF(L39>75,3,IF(L39>50,2,IF(L39>35,1,0))) -> 1 | N39: =IF(L39<35,"FAIL","PASS") -> PASS
D40: 26 | E40: BTMC24O1026 | F40: 0 | G40: 12 | H40: 7 | I40: 2 | J40: =I40+H40 -> 9 | K40: 10 | L40: =K40+J40+G40+F40 -> 31 | M40: =IF(L40>75,3,IF(L40>50,2,IF(L40>35,1,0))) -> 0 | N40: =IF(L40<35,"FAIL","PASS") -> FAIL
D41: 27 | E41: BTMC24O1027 | F41: 9 | G41: 14 | H41: 9 | I41: 12 | J41: =I41+H41 -> 21 | K41: 6 | L41: =K41+J41+G41+F41 -> 50 | M41: =IF(L41>75,3,IF(L41>50,2,IF(L41>35,1,0))) -> 1 | N41: =IF(L41<35,"FAIL","PASS") -> PASS
D42: 28 | E42: BTMC24O1028 | F42: 4 | G42: 8 | H42: 7 | I42: 20 | J42: =I42+H42 -> 27 | K42: 8 | L42: =K42+J42+G42+F42 -> 47 | M42: =IF(L42>75,3,IF(L42>50,2,IF(L42>35,1,0))) -> 1 | N42: =IF(L42<35,"FAIL","PASS") -> PASS
D43: 29 | E43: BTMC24O1029 | F43: 15 | G43: 4 | H43: 8 | I43: 5 | J43: =I43+H43 -> 13 | K43: 28 | L43: =K43+J43+G43+F43 -> 60 | M43: =IF(L43>75,3,IF(L43>50,2,IF(L43>35,1,0))) -> 2 | N43: =IF(L43<35,"FAIL","PASS") -> PASS
D44: 30 | E44: BTMC24O1030 | F44: 15 | G44: 6 | H44: 7 | I44: 19 | J44: =I44+H44 -> 26 | K44: 13 | L44: =K44+J44+G44+F44 -> 60 | M44: =IF(L44>75,3,IF(L44>50,2,IF(L44>35,1,0))) -> 2 | N44: =IF(L44<35,"FAIL","PASS") -> PASS
D45: 31 | E45: BTMC24O1031 | F45: 12 | G45: 11 | H45: 2 | I45: 9 | J45: =I45+H45 -> 11 | K45: 12 | L45: =K45+J45+G45+F45 -> 46 | M45: =IF(L45>75,3,IF(L45>50,2,IF(L45>35,1,0))) -> 1 | N45: =IF(L45<35,"FAIL","PASS") -> PASS
D46: 32 | E46: BTMC24O1032 | F46: 6 | G46: 10 | H46: 5 | I46: 10 | J46: =I46+H46 -> 15 | K46: 27 | L46: =K46+J46+G46+F46 -> 58 | M46: =IF(L46>75,3,IF(L46>50,2,IF(L46>35,1,0))) -> 2 | N46: =IF(L46<35,"FAIL","PASS") -> PASS
... D114: 100 | E114: BTMC24O1100 | F114: 3 | G114: 13 | H114: 7 | I114: 14 | J114: =I114+H114 -> 21 | K114: 29 | L114: =K114+J114+G114+F114 -> 66 | M114: =IF(L114>75,3,IF(L114>50,2,IF(L114>35,1,0))) -> 2 | N114: =IF(L114<35,"FAIL","PASS") -> PASS

Sheet SUB-4
D2: माधव प्रौद्योगिकी एवं विज्ञान संस्थान, ग्वालियर (म.प्र.), भारत
D4: Madhav Institute of Technology & Science DU, Gwalior (M.P.), INDIA
D5: Deemed University
D6: (Declared under Distinct Category by Ministry of Education, Government of India)
G7: NAAC ACCREDITED WITH A++ GRADE
D8: Department of Engineering Mathematics & Computing
D9: B. Tech. I Semester (MAC)
E11: 25241104 | F11: DC | H11: DIGITAL LOGIC DESIGN
D12: S.No | E12: ENROLLMENT NO. | F12: Minor-1 | G12: Minor-2 | H12: Quiz | I12: Assignment | J12: Quiz+Assignment | K12: Major | L12: Total | M12: CREDIT | N12: Result
F13: 20 | G13: 20 | H13: 10 | I13: 20 | J13: 30 | K13: 30 | L13: 100 | M13: 3 | N13: PASS/FAIL
D15: 1 | E15: BTMC24O1001 | F15: 7 | G15: 13 | H15: 6 | I15: 13 | J15: =H15+I15 -> 19 | K15: 8 | L15: =K15+J15+G15+F15 -> 47 | M15: =IF(L15>75,3,IF(L15>50,2,IF(L15>35,1,0))) -> 1 | N15: =IF(L15<35,"FAIL","PASS") -> PASS | P15: CLASS OVERVIEW
D16: 2 | E16: BTMC24O1002 | F16: 7 | G16: 2 | H16: 1 | I16: 0 | J16: =H16+I16 -> 1 | K16: 4 | L16: =K16+J16+G16+F16 -> 14 | M16: =IF(L16>75,3,IF(L16>50,2,IF(L16>35,1,0))) -> 0 | N16: =IF(L16<35,"FAIL","PASS") -> FAIL | P16: PASSED : | Q16: =COUNTIF(N15:N114,"PASS") -> 87
D17: 3 | E17: BTMC24O1003 | F17: 0 | G17: 3 | H17: 10 | I17: 11 | J17: =H17+I17 -> 21 | K17: 12 | L17: =K17+J17+G17+F17 -> 36 | M17: =IF(L17>75,3,IF(L17>50,2,IF(L17>35,1,0))) -> 1 | N17: =IF(L17<35,"FAIL","PASS") -> PASS | P17: FAILED : | Q17: =COUNTIF(N15:N114,"FAIL") -> 13
D18: 4 | E18: BTMC24O1004 | F18: 1 | G18: 19 | H18: 3 | I18: 14 | J18: =H18+I18 -> 17 | K18: 25 | L18: =K18+J18+G18+F18 -> 62 | M18: =IF(L18>75,3,IF(L18>50,2,IF(L18>35,1,0))) -> 2 | N18: =IF(L18<35,"FAIL","PASS") -> PASS
D19: 5 | E19: BTMC24O1005 | F19: 18 | G19: 7 | H19: 0 | I19: 4 | J19: =H19+I19 -> 4 | K19: 6 | L19: =K19+J19+G19+F19 -> 35 | M19: =IF(L19>75,3,IF(L19>50,2,IF(L19>35,1,0))) -> 0 | N19: =IF(L19<35,"FAIL","PASS") -> PASS
D20: 6 | E20: BTMC24O1006 | F20: 0 | G20: 13 | H20: 5 | I20: 20 | J20: =H20+I20 -> 25 | K20: 19 | L20: =K20+J20+G20+F20 -> 57 | M20: =IF(L20>75,3,IF(L20>50,2,IF(L20>35,1,0))) -> 2 | N20: =IF(L20<35,"FAIL","PASS") -> PASS
D21: 7 | E21: BTMC24O1007 | F21: 2 | G21: 15 | H21: 4 | I21: 17 | J21: =H21+I21 -> 21 | K21: 17 | L21: =K21+J21+G21+F21 -> 55 | M21: =IF(L21>75,3,IF(L21>50,2,IF(L21>35,1,0))) -> 2 | N21: =IF(L21<35,"FAIL","PASS") -> PASS
D22: 8 | E22: BTMC24O1008 | F22: 2 | G22: 6 | H22: 4 | I22: 15 | J22: =H22+I22 -> 19 | K22: 12 | L22: =K22+J22+G22+F22 -> 39 | M22: =IF(L22>75,3,IF(L22>50,2,IF(L22>35,1,0))) -> 1 | N22: =IF(L22<35,"FAIL","PASS") -> PASS
D23: 9 | E23: BTMC24O1009 | F23: 16 | G23: 19 | H23: 4 | I23: 15 | J23: =H23+I23 -> 19 | K23: 9 | L23: =K23+J23+G23+F23 -> 63 | M23: =IF(L23>75,3,IF(L23>50,2,IF(L23>35,1,0))) -> 2 | N23: =IF(L23<35,"FAIL","PASS") -> PASS
D24: 10 | E24: BTMC24O1010 | F24: 2 | G24: 13 | H24: 1 | I24: 4 | J24: =H24+I24 -> 5 | K24: 9 | L24: =K24+J24+G24+F24 -> 29 | M24: =IF(L24>75,3,IF(L24>50,2,IF(L24>35,1,0))) -> 0 | N24: =IF(L24<35,"FAIL","PASS") -> FAIL
D25: 11 | E25: BTMC24O1011 | F25: 5 | G25: 6 | H25: 2 | I25: 13 | J25: =H25+I25 -> 15 | K25: 9 | L25: =K25+J25+G25+F25 -> 35 | M25: =IF(L25>75,3,IF(L25>50,2,IF(L25>35,1,0))) -> 0 | N25: =IF(L25<35,"FAIL","PASS") -> PASS
D26: 12 | E26: BTMC24O1012 | F26: 9 | G26: 10 | H26: 6 | I26: 14 | J26: =H26+I26 -> 20 | K26: 2 | L26: =K26+J26+G26+F26 -> 41 | M26: =IF(L26>75,3,IF(L26>50,2,IF(L26>35,1,0))) -> 1 | N26: =IF(L26<35,"FAIL","PASS") -> PASS
D27: 13 | E27: BTMC24O1013 | F27: 18 | G27: 1 | H27: 1 | I27: 19 | J27: =H27+I27 -> 20 | K27: 28 | L27: =K27+J27+G27+F27 -> 67 | M27: =IF(L27>75,3,IF(L27>50,2,IF(L27>35,1,0))) -> 2 | N27: =IF(L27<35,"FAIL","PASS") -> PASS
D28: 14 | E28: BTMC24O1014 | F28: 13 | G28: 20 | H28: 7 | I28: 19 | J28: =H28+I28 -> 26 | K28: 14 | L28: =K28+J28+G28+F28 -> 73 | M28: =IF(L28>75,3,IF(L28>50,2,IF(L28>35,1,0))) -> 2 | N28: =IF(L28<35,"FAIL","PASS") -> PASS
D29: 15 | E29: BTMC24O1015 | F29: 7 | G29: 12 | H29: 3 | I29: 1 | J29: =H29+I29 -> 4 | K29: 13 | L29: =K29+J29+G29+F29 -> 36 | M29: =IF(L29>75,3,IF(L29>50,2,IF(L29>35,1,0))) -> 1 | N29: =IF(L29<35,"FAIL","PASS") -> PASS
... D34: 20 | E34: BTMC24O1020 | F34: 6 | G34: 15 | H34: 6 | I34: 9 | J34: =H34+I34 -> 15 | K34: 21 | L34: =K34+J34+G34+F34 -> 57 | M34: =IF(L34>75,3,IF(L34>50,2,IF(L34>35,1,0))) -> 2 | N34: =IF(L34<35,"FAIL","PASS") -> PASS
D35: 21 | E35: ='SUB-1'!E35 -> BTMC24O1021 | F35: 15 | G35: 15 | H35: 9 | I35: 15 | J35: =H35+I35 -> 24 | K35: 27 | L35: =K35+J35+G35+F35 -> 81 | M35: =IF(L35>75,3,IF(L35>50,2,IF(L35>35,1,0))) -> 3 | N35: =IF(L35<35,"FAIL","PASS") -> PASS
D36: 22 | E36: ='SUB-1'!E36 -> BTMC24O1022 | F36: 10 | G36: 4 | H36: 7 | I36: 20 | J36: =H36+I36 -> 27 | K36: 28 | L36: =K36+J36+G36+F36 -> 69 | M36: =IF(L36>75,3,IF(L36>50,2,IF(L36>35,1,0))) -> 2 | N36: =IF(L36<35,"FAIL","PASS") -> PASS
D37: 23 | E37: ='SUB-1'!E37 -> BTMC24O1023 | F37: 20 | G37: 2 | H37: 10 | I37: 14 | J37: =H37+I37 -> 24 | K37: 29 | L37: =K37+J37+G37+F37 -> 75 | M37: =IF(L37>75,3,IF(L37>50,2,IF(L37>35,1,0))) -> 2 | N37: =IF(L37<35,"FAIL","PASS") -> PASS
D38: 24 | E38: ='SUB-1'!E38 -> BTMC24O1024 | F38: 2 | G38: 8 | H38: 1 | I38: 0 | J38: =H38+I38 -> 1 | K38: 18 | L38: =K38+J38+G38+F38 -> 29 | M38: =IF(L38>75,3,IF(L38>50,2,IF(L38>35,1,0))) -> 0 | N38: =IF(L38<35,"FAIL","PASS") -> FAIL
D39: 25 | E39: ='SUB-1'!E39 -> BTMC24O1025 | F39: 4 | G39: 19 | H39: 3 | I39: 13 | J39: =H39+I39 -> 16 | K39: 24 | L39: =K39+J39+G39+F39 -> 63 | M39: =IF(L39>75,3,IF(L39>50,2,IF(L39>35,1,0))) -> 2 | N39: =IF(L39<35,"FAIL","PASS") -> PASS
D40: 26 | E40: ='SUB-1'!E40 -> BTMC24O1026 | F40: 15 | G40: 0 | H40: 4 | I40: 2 | J40: =H40+I40 -> 6 | K40: 12 | L40: =K40+J40+G40+F40 -> 33 | M40: =IF(L40>75,3,IF(L40>50,2,IF(L40>35,1,0))) -> 0 | N40: =IF(L40<35,"FAIL","PASS") -> FAIL
D41: 27 | E41: ='SUB-1'!E41 -> BTMC24O1027 | F41: 9 | G41: 3 | H41: 5 | I41: 14 | J41: =H41+I41 -> 19 | K41: 18 | L41: =K41+J41+G41+F41 -> 49 | M41: =IF(L41>75,3,IF(L41>50,2,IF(L41>35,1,0))) -> 1 | N41: =IF(L41<35,"FAIL","PASS") -> PASS
D42: 28 | E42: ='SUB-1'!E42 -> BTMC24O1028 | F42: 5 | G42: 11 | H42: 9 | I42: 14 | J42: =H42+I42 -> 23 | K42: 10 | L42: =K42+J42+G42+F42 -> 49 | M42: =IF(L42>75,3,IF(L42>50,2,IF(L42>35,1,0))) -> 1 | N42: =IF(L42<35,"FAIL","PASS") -> PASS
D43: 29 | E43: ='SUB-1'!E43 -> BTMC24O1029 | F43: 9 | G43: 11 | H43: 8 | I43: 14 | J43: =H43+I43 -> 22 | K43: 30 | L43: =K43+J43+G43+F43 -> 72 | M43: =IF(L43>75,3,IF(L43>50,2,IF(L43>35,1,0))) -> 2 | N43: =IF(L43<35,"FAIL","PASS") -> PASS
D44: 30 | E44: ='SUB-1'!E44 -> BTMC24O1030 | F44: 17 | G44: 1 | H44: 9 | I44: 11 | J44: =H44+I44 -> 20 | K44: 17 | L44: =K44+J44+G44+F44 -> 55 | M44: =IF(L44>75,3,IF(L44>50,2,IF(L44>35,1,0))) -> 2 | N44: =IF(L44<35,"FAIL","PASS") -> PASS
D45: 31 | E45: ='SUB-1'!E45 -> BTMC24O1031 | F45: 5 | G45: 9 | H45: 6 | I45: 20 | J45: =H45+I45 -> 26 | K45: 8 | L45: =K45+J45+G45+F45 -> 48 | M45: =IF(L45>75,3,IF(L45>50,2,IF(L45>35,1,0))) -> 1 | N45: =IF(L45<35,"FAIL","PASS") -> PASS
D46: 32 | E46: ='SUB-1'!E46 -> BTMC24O1032 | F46: 13 | G46: 19 | H46: 5 | I46: 0 | J46: =H46+I46 -> 5 | K46: 12 | L46: =K46+J46+G46+F46 -> 49 | M46: =IF(L46>75,3,IF(L46>50,2,IF(L46>35,1,0))) -> 1 | N46: =IF(L46<35,"FAIL","PASS") -> PASS
... D114: 100 | E114: ='SUB-1'!E114 -> BTMC24O1100 | F114: 1 | G114: 6 | H114: 9 | I114: 16 | J114: =H114+I114 -> 25 | K114: 4 | L114: =K114+J114+G114+F114 -> 36 | M114: =IF(L114>75,3,IF(L114>50,2,IF(L114>35,1,0))) -> 1 | N114: =IF(L114<35,"FAIL","PASS") -> PASS

Sheet SUB-5
D2: माधव प्रौद्योगिकी एवं विज्ञान संस्थान, ग्वालियर (म.प्र.), भारत
D4: Madhav Institute of Technology & Science DU, Gwalior (M.P.), INDIA
D5: Deemed University
D6: (Declared under Distinct Category by Ministry of Education, Government of India)
G7: NAAC ACCREDITED WITH A++ GRADE
D8: Department of Engineering Mathematics & Computing
D9: B. Tech. I Semester (MAC)
E11: 25241105 | F11: BSC | H11: DIFFERENTIAL EQUATIONS
D12: S.No | E12: ENROLLMENT NO. | F12: Minor-1 | G12: Minor-2 | H12: Quiz | I12: Assignment | J12: Quiz+Assignment | K12: Major | L12: Total | M12: CREDIT | N12: Result
F13: 20 | G13: 20 | H13: 10 | I13: 20 | J13: 30 | K13: 30 | L13: 100 | M13: 3 | N13: PASS/FAIL
D15: 1 | E15: BTMC24O1001 | F15: 4 | G15: 10 | H15: 3 | I15: 8 | J15: =H15+I15 -> 11 | K15: 24 | L15: =K15+J15+G15+F15 -> 49 | M15: =IF(L15>75,3,IF(L15>50,2,IF(L15>35,1,0))) -> 1 | N15: =IF(L15<35,"FAIL","PASS") -> PASS | P15: CLASS OVERVIEW
D16: 2 | E16: BTMC24O1002 | F16: 6 | G16: 7 | H16: 2 | I16: 14 | J16: =H16+I16 -> 16 | K16: 26 | L16: =K16+J16+G16+F16 -> 55 | M16: =IF(L16>75,3,IF(L16>50,2,IF(L16>35,1,0))) -> 2 | N16: =IF(L16<35,"FAIL","PASS") -> PASS | P16: PASSED : | Q16: =COUNTIF(N15:N114,"PASS") -> 81
